Workbook
Name DVerweis: _xlfn.LAMBDA(_xlpm.Such1,_xlpm.Such2,_xlpm.Matrix1,_xlpm.Matrix2,_xlpm.WertMatrix, _xlfn.XLOOKUP(_xlpm.Such1, _xlpm.Matrix1, _xlfn.XLOOKUP(_xlpm.Such2, _xlpm.Matrix2, _xlpm.WertMatrix, 0), NA()))
Name EntfernungPythagoras: _xlfn.LAMBDA(_xlpm.Länge1,_xlpm.Breite1,_xlpm.Länge2,_xlpm.Breite2, SQRT( SUMSQ( (_xlpm.Länge1 - _xlpm.Länge2), (_xlpm.Breite1 - _xlpm.Breite2) ) ) )
Name iSpalte: _xlfn.LAMBDA(_xlpm.Zelle,COLUMN(INDIRECT(_xlpm.Zelle)))
Name IstPrimzahl: _xlfn.LAMBDA(_xlpm.Zahl, _xlfn.IFS(_xlpm.Zahl <= 1, FALSE, _xlpm.Zahl = 2, TRUE, TRUE, SUMPRODUCT(--(MOD(_xlpm.Zahl, _xlfn.SEQUENCE(ROUNDUP(SQRT(_xlpm.Zahl), 0) - 1, 1, 2)) = 0)) = 0))
Name iZeile: _xlfn.LAMBDA(_xlpm.Zelle,ROW(INDIRECT(_xlpm.Zelle)))
Name m2s: _xlfn.LAMBDA(_xlpm.m2s,_xlpm.m2s*60*60*24*1000)
Name NurZahlen: _xlfn.LAMBDA(_xlpm.Text, _xlfn.REGEXEXTRACT(_xlpm.Text, "\d+", 1)*1)
Name SpielKarten_Bereinigen: _xlfn.LAMBDA(_xlpm.Feld,SUBSTITUTE(_xlpm.Feld,"0",""))
Name SpielKarten_ZelleTrennen: _xlfn.LAMBDA(_xlpm.KartenStapelZelle,SUBSTITUTE(MID(SUBSTITUTE(_xlpm.KartenStapelZelle,10,"x"),_xlfn.SEQUENCE(,LEN(_xlpm.KartenStapelZelle)/2,,2),2),"x",10))
Name ST: _xlfn.LAMBDA(_xlpm.text,_xlfn.TEXTSPLIT(_xlpm.text,";"))
Name WennLeer: _xlfn.LAMBDA(_xlpm.Wert,_xlpm.Ersatzwert,IF(ISBLANK(_xlpm.Wert),_xlpm.Ersatzwert,_xlpm.Wert))
Name Würfel2Zahl: _xlfn.LAMBDA(_xlpm.Würfel, IF(ZwischenWert(_xlfn.UNICODE(_xlpm.Würfel), 9856, 9861, 0), _xlfn.UNICODE(_xlpm.Würfel) - 9855, "#keinWürfel"))
Name xEindeutig: _xlfn.LAMBDA(_xlpm.Matrix, _xlfn.UNIQUE(_xlfn.TOCOL(_xlpm.Matrix, 3)))
Name xRest: _xlfn.LAMBDA(_xlpm.a,_xlpm.b, IF(MOD(_xlpm.a, _xlpm.b) = 0, _xlpm.b, MOD(_xlpm.a, _xlpm.b)))
Name Zahl2Text: _xlfn.LAMBDA(_xlpm.Zahl,_xlfn.TEXTBEFORE(_xlfn.TRANSLATE(BAHTTEXT(_xlpm.Zahl), , "de"), " Baht"))

Sheet Case
B2: MEWC DACH - Qualifikationsrunde 3
B4: Bodensee | J4: Case Autor
B5: #VALUE! | J5: #VALUE!
J12: Julian Pöltl
B14: Anweisungen
B15: Willkommen zu dieser Qualifikationsrunde von MEWC DACH.
B16: Der Bodensee, einer der größten Seen Europas, liegt im Zentrum der DACH-Region. Am Fuße der Alpen grenzt er an Deutschland, Österreich und die Schweiz...und auch Liechtenstein ist nicht weit entfernt. In diesem Fall wirst du dich mit der Modellierung auf der Grundlage von Zu- und Abflüssen sowie mit einigen Map-Aufgaben befassen. Alle erforderlichen Informationen werden beim entsprechenden Level bereitgestellt.
B17: Viel Erfolg!
B19: Bonusfragen
B21: Um es noch spannender zu machen, gibt es 5 zusätzliche Bonusaufgaben.
B23: Spiel # | C23: Verwandt mit Level # | D23: Punkte | E23: Antwort | G23: Fragen
B24: Bonus 1 | C24: 1/2 | D24: 30 | E24: Alpenrhein | G24: Welcher Fluss liefert den größten Gesamtzufluss?
B25: Bonus 2 | C25: 1/2 | D25: 40 | E25: 50369472000 | G25: Wie hoch ist der gesamte Zufluss (nur Flüsse) in Litern am Tag mit dem höchsten Zufluss?
B26: Bonus 3 | C26: 4 | D26: 50 | E26: 46315 | G26: Basierend auf den Regeln von Level 4: An welchem Tag ist der Pegel am niedrigsten?
B27: Bonus 4 | C27: 5 | D27: 60 | E27: 8 | G27: Wie viele Städte auf der Karte (!) gibt es in der Schweiz?
B28: Bonus 5 | C28: 6 | D28: 70 | E28: 69 | G28: Wie groß ist die größte Entfernung zwischen zwei Städten? (Runde auf volle Kilometer)
B30: Questions
B32: Level 1 | C32: Einfach | D32: Alpenrhein
B34: Wie hoch ist der Zufluss des Alpenrheins in l/d (Liter pro Tag) zum entsprechenden Datum?
B35: Die Zuflüsse in der Zuflusstabelle sind in m³/s angegeben (1 m³ = 1.000 l).
B36: Runde auf den nächstgelegenen Liter.
B38: Beispiel:
B39: Der Zufluss des Alpenrheins beträgt am 21. April 2026 397,80 m³/s.
B40: 397,80 m³/s entsprechen 397.800,0 l/s (pro Sekunde).
B41: 397.800 l/s entsprechen 23.868.000 l/min (pro Minute).
B42: 23.868.000 l/min entsprechen 1.432.080.000 l/h (pro Stunde).
B43: Der Zufluss an diesem Tag beträgt daher 34.369.920.000 Liter.
B45: Spiel # | C45: Level | D45: Punkte | E45: Antwort | G45: Datum
B47: Beispiel1 | C47: 1 | D47: 0 | E47: 34369920000 | G47: 46133 | H47: =_xlfn.XLOOKUP(G47,'Zuflüsse - Flüsse'!A:A,'Zuflüsse - Flüsse'!B:B) -> 397.8 | I47: =H47*60*60*24*1000 -> 34369920000 | J47: =I47=E47 -> TRUE
B49: 1 | C49: 1 | D49: 2 | E49: 2.8578528e+10 | G49: 46081 | H49: =_xlfn.XLOOKUP(G49,'Zuflüsse - Flüsse'!A:A,'Zuflüsse - Flüsse'!B:B) -> 330.77 | I49: =H49*60*60*24*1000 -> 2.8578528e+10
B50: 2 | C50: 1 | D50: 2 | E50: 27306720000 | G50: 46128 | H50: =_xlfn.XLOOKUP(G50,'Zuflüsse - Flüsse'!A:A,'Zuflüsse - Flüsse'!B:B) -> 316.05 | I50: =H50*60*60*24*1000 -> 27306720000
B51: 3 | C51: 1 | D51: 2 | E51: 38154240000 | G51: 46183 | H51: =_xlfn.XLOOKUP(G51,'Zuflüsse - Flüsse'!A:A,'Zuflüsse - Flüsse'!B:B) -> 441.6 | I51: =H51*60*60*24*1000 -> 38154240000
B52: 4 | C52: 1 | D52: 2 | E52: 36803808000 | G52: 46221 | H52: =_xlfn.XLOOKUP(G52,'Zuflüsse - Flüsse'!A:A,'Zuflüsse - Flüsse'!B:B) -> 425.97 | I52: =H52*60*60*24*1000 -> 36803808000
B53: 5 | C53: 1 | D53: 2 | E53: 7.743168e+09 | G53: 46309 | H53: =_xlfn.XLOOKUP(G53,'Zuflüsse - Flüsse'!A:A,'Zuflüsse - Flüsse'!B:B) -> 89.62 | I53: =H53*60*60*24*1000 -> 7.743168e+09
B54: 6 | C54: 1 | D54: 2 | E54: 2.8696896e+10 | G54: 46146 | H54: =_xlfn.XLOOKUP(G54,'Zuflüsse - Flüsse'!A:A,'Zuflüsse - Flüsse'!B:B) -> 332.14 | I54: =H54*60*60*24*1000 -> 2.8696896e+10
B55: 7 | C55: 1 | D55: 2 | E55: 14546304000 | G55: 46135 | H55: =_xlfn.XLOOKUP(G55,'Zuflüsse - Flüsse'!A:A,'Zuflüsse - Flüsse'!B:B) -> 168.36 | I55: =H55*60*60*24*1000 -> 14546304000
B56: 8 | C56: 1 | D56: 2 | E56: 5.135616e+09 | G56: 46331 | H56: =_xlfn.XLOOKUP(G56,'Zuflüsse - Flüsse'!A:A,'Zuflüsse - Flüsse'!B:B) -> 59.44 | I56: =H56*60*60*24*1000 -> 5.135616e+09
B57: 9 | C57: 1 | D57: 2 | E57: 5.135616e+09 | G57: 46357 | H57: =_xlfn.XLOOKUP(G57,'Zuflüsse - Flüsse'!A:A,'Zuflüsse - Flüsse'!B:B) -> 59.44 | I57: =H57*60*60*24*1000 -> 5.135616e+09
B58: 10 | C58: 1 | D58: 2 | E58: 1.2253248e+10 | G58: 46112 | H58: =_xlfn.XLOOKUP(G58,'Zuflüsse - Flüsse'!A:A,'Zuflüsse - Flüsse'!B:B) -> 141.82 | I58: =H58*60*60*24*1000 -> 1.2253248e+10
B59: 11 | C59: 1 | D59: 2 | E59: 7.744032e+09 | G59: 46336 | H59: =_xlfn.XLOOKUP(G59,'Zuflüsse - Flüsse'!A:A,'Zuflüsse - Flüsse'!B:B) -> 89.63 | I59: =H59*60*60*24*1000 -> 7.744032e+09
...

Sheet F7
A1: =IF(ADDRESS(ROW(),COLUMN(),4)=$CB$5,1,999) -> 999 | B1: =IF(ADDRESS(ROW(),COLUMN(),4)=$CB$5,1,999) -> 999 | C1: =IF(ADDRESS(ROW(),COLUMN(),4)=$CB$5,1,999) -> 999 | D1: =IF(ADDRESS(ROW(),COLUMN(),4)=$CB$5,1,999) -> 999 | E1: =IF(ADDRESS(ROW(),COLUMN(),4)=$CB$5,1,999) -> 999 | F1: =IF(ADDRESS(ROW(),COLUMN(),4)=$CB$5,1,999) -> 999 | G1: =IF(ADDRESS(ROW(),COLUMN(),4)=$CB$5,1,999) -> 999 | H1: =IF(ADDRESS(ROW(),COLUMN(),4)=$CB$5,1,999) -> 999 | ... BX1: =IF(ADDRESS(ROW(),COLUMN(),4)=$CB$5,1,999) -> 999
A2: =IF(ADDRESS(ROW(),COLUMN(),4)=$CB$5,1,999) -> 999 | B2: =IF(ADDRESS(ROW(),COLUMN(),4)=$CB$5,1,999) -> 999 | C2: =IF(ADDRESS(ROW(),COLUMN(),4)=$CB$5,1,999) -> 999 | D2: =IF(ADDRESS(ROW(),COLUMN(),4)=$CB$5,1,999) -> 999 | E2: =IF(ADDRESS(ROW(),COLUMN(),4)=$CB$5,1,999) -> 999 | F2: =IF(ADDRESS(ROW(),COLUMN(),4)=$CB$5,1,999) -> 999 | G2: =IF(ADDRESS(ROW(),COLUMN(),4)=$CB$5,1,999) -> 999 | H2: =IF(ADDRESS(ROW(),COLUMN(),4)=$CB$5,1,999) -> 999 | ... BX2: =IF(ADDRESS(ROW(),COLUMN(),4)=$CB$5,1,999) -> 999
A3: =IF(ADDRESS(ROW(),COLUMN(),4)=$CB$5,1,999) -> 999 | B3: =IF(ADDRESS(ROW(),COLUMN(),4)=$CB$5,1,999) -> 999 | C3: =IF(ADDRESS(ROW(),COLUMN(),4)=$CB$5,1,999) -> 999 | D3: =IF(ADDRESS(ROW(),COLUMN(),4)=$CB$5,1,999) -> 999 | E3: =IF(ADDRESS(ROW(),COLUMN(),4)=$CB$5,1,999) -> 999 | F3: =IF(ADDRESS(ROW(),COLUMN(),4)=$CB$5,1,999) -> 999 | G3: =IF(ADDRESS(ROW(),COLUMN(),4)=$CB$5,1,999) -> 999 | H3: =IF(ADDRESS(ROW(),COLUMN(),4)=$CB$5,1,999) -> 999 | ... BX3: =IF(ADDRESS(ROW(),COLUMN(),4)=$CB$5,1,999) -> 999 | CA3: Beispiel7 | CB3: {=_xlfn.XLOOKUP(CA3,Case!B285:B306,Case!G285:H306)} -> Stein am Rhein | CC3: Arbon
A4: =IF(ADDRESS(ROW(),COLUMN(),4)=$CB$5,1,999) -> 999 | B4: =IF(ADDRESS(ROW(),COLUMN(),4)=$CB$5,1,999) -> 999 | C4: =IF(ADDRESS(ROW(),COLUMN(),4)=$CB$5,1,999) -> 999 | D4: =IF(ADDRESS(ROW(),COLUMN(),4)=$CB$5,1,999) -> 999 | E4: =IF(ADDRESS(ROW(),COLUMN(),4)=$CB$5,1,999) -> 999 | F4: =IF(ADDRESS(ROW(),COLUMN(),4)=$CB$5,1,999) -> 999 | G4: =IF(ADDRESS(ROW(),COLUMN(),4)=$CB$5,1,999) -> 999 | H4: =IF(ADDRESS(ROW(),COLUMN(),4)=$CB$5,1,999) -> 999 | ... BX4: =IF(ADDRESS(ROW(),COLUMN(),4)=$CB$5,1,999) -> 999
A5: =IF(ADDRESS(ROW(),COLUMN(),4)=$CB$5,1,999) -> 999 | B5: =IF(ADDRESS(ROW(),COLUMN(),4)=$CB$5,1,999) -> 999 | C5: =IF(ADDRESS(ROW(),COLUMN(),4)=$CB$5,1,999) -> 999 | D5: =IF(ADDRESS(ROW(),COLUMN(),4)=$CB$5,1,999) -> 999 | E5: =IF(ADDRESS(ROW(),COLUMN(),4)=$CB$5,1,999) -> 999 | F5: =IF(ADDRESS(ROW(),COLUMN(),4)=$CB$5,1,999) -> 999 | G5: =IF(ADDRESS(ROW(),COLUMN(),4)=$CB$5,1,999) -> 999 | H5: =IF(ADDRESS(ROW(),COLUMN(),4)=$CB$5,1,999) -> 999 | ... BX5: =IF(ADDRESS(ROW(),COLUMN(),4)=$CB$5,1,999) -> 999 | CB5: =_xlfn.XLOOKUP(CB3,K2Länder!$G:$G,K2Länder!$F:$F) -> D23 | CC5: =_xlfn.XLOOKUP(CC3,K2Länder!$G:$G,K2Länder!$F:$F) -> AV39
A6: =IF(ADDRESS(ROW(),COLUMN(),4)=$CB$5,1,999) -> 999 | B6: =IF(ADDRESS(ROW(),COLUMN(),4)=$CB$5,1,999) -> 999 | C6: =IF(ADDRESS(ROW(),COLUMN(),4)=$CB$5,1,999) -> 999 | D6: =IF(ADDRESS(ROW(),COLUMN(),4)=$CB$5,1,999) -> 999 | E6: =IF(ADDRESS(ROW(),COLUMN(),4)=$CB$5,1,999) -> 999 | F6: =IF(ADDRESS(ROW(),COLUMN(),4)=$CB$5,1,999) -> 999 | G6: =IF(ADDRESS(ROW(),COLUMN(),4)=$CB$5,1,999) -> 999 | H6: =IF(ADDRESS(ROW(),COLUMN(),4)=$CB$5,1,999) -> 999 | ... Q6: =IF(ADDRESS(ROW(),COLUMN(),4)=$CB$5,1,999) -> 999 | R6: =IF(MIN(Q6,R5,S6,R7)>MIN(Q5,Q7,S5,S7),MIN(Q5,Q7,S5,S7)+SQRT(2),MIN(Q6,R5,S6,R7)+1) -> 54.870058 | S6: =IF(MIN(R6,S5,T6,S7)>MIN(R5,R7,T5,T7),MIN(R5,R7,T5,T7)+SQRT(2),MIN(R6,S5,T6,S7)+1) -> 53.870058 | T6: =IF(MIN(S6,T5,U6,T7)>MIN(S5,S7,U5,U7),MIN(S5,S7,U5,U7)+SQRT(2),MIN(S6,T5,U6,T7)+1) -> 52.870058 | U6: =IF(ADDRESS(ROW(),COLUMN(),4)=$CB$5,1,999) -> 999 | V6: =IF(ADDRESS(ROW(),COLUMN(),4)=$CB$5,1,999) -> 999 | W6: =IF(ADDRESS(ROW(),COLUMN(),4)=$CB$5,1,999) -> 999 | X6: =IF(ADDRESS(ROW(),COLUMN(),4)=$CB$5,1,999) -> 999 | Y6: =IF(ADDRESS(ROW(),COLUMN(),4)=$CB$5,1,999) -> 999 | Z6: =IF(ADDRESS(ROW(),COLUMN(),4)=$CB$5,1,999) -> 999 | AA6: =IF(ADDRESS(ROW(),COLUMN(),4)=$CB$5,1,999) -> 999 | AB6: =IF(ADDRESS(ROW(),COLUMN(),4)=$CB$5,1,999) -> 999 | ... BX6: =IF(ADDRESS(ROW(),COLUMN(),4)=$CB$5,1,999) -> 999
A7: =IF(ADDRESS(ROW(),COLUMN(),4)=$CB$5,1,999) -> 999 | B7: =IF(ADDRESS(ROW(),COLUMN(),4)=$CB$5,1,999) -> 999 | C7: =IF(ADDRESS(ROW(),COLUMN(),4)=$CB$5,1,999) -> 999 | D7: =IF(ADDRESS(ROW(),COLUMN(),4)=$CB$5,1,999) -> 999 | E7: =IF(ADDRESS(ROW(),COLUMN(),4)=$CB$5,1,999) -> 999 | F7: =IF(ADDRESS(ROW(),COLUMN(),4)=$CB$5,1,999) -> 999 | G7: =IF(ADDRESS(ROW(),COLUMN(),4)=$CB$5,1,999) -> 999 | H7: =IF(ADDRESS(ROW(),COLUMN(),4)=$CB$5,1,999) -> 999 | ... Q7: =IF(ADDRESS(ROW(),COLUMN(),4)=$CB$5,1,999) -> 999 | R7: =IF(MIN(Q7,R6,S7,R8)>MIN(Q6,Q8,S6,S8),MIN(Q6,Q8,S6,S8)+SQRT(2),MIN(Q7,R6,S7,R8)+1) -> 54.455844 | S7: =IF(MIN(R7,S6,T7,S8)>MIN(R6,R8,T6,T8),MIN(R6,R8,T6,T8)+SQRT(2),MIN(R7,S6,T7,S8)+1) -> 53.455844 | T7: =IF(MIN(S7,T6,U7,T8)>MIN(S6,S8,U6,U8),MIN(S6,S8,U6,U8)+SQRT(2),MIN(S7,T6,U7,T8)+1) -> 52.455844 | U7: =IF(MIN(T7,U6,V7,U8)>MIN(T6,T8,V6,V8),MIN(T6,T8,V6,V8)+SQRT(2),MIN(T7,U6,V7,U8)+1) -> 51.455844 | V7: =IF(ADDRESS(ROW(),COLUMN(),4)=$CB$5,1,999) -> 999 | W7: =IF(ADDRESS(ROW(),COLUMN(),4)=$CB$5,1,999) -> 999 | X7: =IF(ADDRESS(ROW(),COLUMN(),4)=$CB$5,1,999) -> 999 | Y7: =IF(ADDRESS(ROW(),COLUMN(),4)=$CB$5,1,999) -> 999 | Z7: =IF(ADDRESS(ROW(),COLUMN(),4)=$CB$5,1,999) -> 999 | AA7: =IF(ADDRESS(ROW(),COLUMN(),4)=$CB$5,1,999) -> 999 | AB7: =IF(ADDRESS(ROW(),COLUMN(),4)=$CB$5,1,999) -> 999 | AC7: =IF(ADDRESS(ROW(),COLUMN(),4)=$CB$5,1,999) -> 999 | ... BX7: =IF(ADDRESS(ROW(),COLUMN(),4)=$CB$5,1,999) -> 999
A8: =IF(ADDRESS(ROW(),COLUMN(),4)=$CB$5,1,999) -> 999 | B8: =IF(ADDRESS(ROW(),COLUMN(),4)=$CB$5,1,999) -> 999 | C8: =IF(ADDRESS(ROW(),COLUMN(),4)=$CB$5,1,999) -> 999 | D8: =IF(ADDRESS(ROW(),COLUMN(),4)=$CB$5,1,999) -> 999 | E8: =IF(ADDRESS(ROW(),COLUMN(),4)=$CB$5,1,999) -> 999 | F8: =IF(ADDRESS(ROW(),COLUMN(),4)=$CB$5,1,999) -> 999 | G8: =IF(ADDRESS(ROW(),COLUMN(),4)=$CB$5,1,999) -> 999 | H8: =IF(ADDRESS(ROW(),COLUMN(),4)=$CB$5,1,999) -> 999 | ... S8: =IF(ADDRESS(ROW(),COLUMN(),4)=$CB$5,1,999) -> 999 | T8: =IF(MIN(S8,T7,U8,T9)>MIN(S7,S9,U7,U9),MIN(S7,S9,U7,U9)+SQRT(2),MIN(S8,T7,U8,T9)+1) -> 52.041631 | U8: =IF(MIN(T8,U7,V8,U9)>MIN(T7,T9,V7,V9),MIN(T7,T9,V7,V9)+SQRT(2),MIN(T8,U7,V8,U9)+1) -> 51.041631 | V8: =IF(MIN(U8,V7,W8,V9)>MIN(U7,U9,W7,W9),MIN(U7,U9,W7,W9)+SQRT(2),MIN(U8,V7,W8,V9)+1) -> 50.041631 | W8: =IF(ADDRESS(ROW(),COLUMN(),4)=$CB$5,1,999) -> 999 | X8: =IF(ADDRESS(ROW(),COLUMN(),4)=$CB$5,1,999) -> 999 | Y8: =IF(ADDRESS(ROW(),COLUMN(),4)=$CB$5,1,999) -> 999 | Z8: =IF(ADDRESS(ROW(),COLUMN(),4)=$CB$5,1,999) -> 999 | AA8: =IF(ADDRESS(ROW(),COLUMN(),4)=$CB$5,1,999) -> 999 | AB8: =IF(ADDRESS(ROW(),COLUMN(),4)=$CB$5,1,999) -> 999 | AC8: =IF(ADDRESS(ROW(),COLUMN(),4)=$CB$5,1,999) -> 999 | AD8: =IF(ADDRESS(ROW(),COLUMN(),4)=$CB$5,1,999) -> 999 | ... BX8: =IF(ADDRESS(ROW(),COLUMN(),4)=$CB$5,1,999) -> 999
A9: =IF(ADDRESS(ROW(),COLUMN(),4)=$CB$5,1,999) -> 999 | B9: =IF(ADDRESS(ROW(),COLUMN(),4)=$CB$5,1,999) -> 999 | C9: =IF(ADDRESS(ROW(),COLUMN(),4)=$CB$5,1,999) -> 999 | D9: =IF(ADDRESS(ROW(),COLUMN(),4)=$CB$5,1,999) -> 999 | E9: =IF(ADDRESS(ROW(),COLUMN(),4)=$CB$5,1,999) -> 999 | F9: =IF(ADDRESS(ROW(),COLUMN(),4)=$CB$5,1,999) -> 999 | G9: =IF(ADDRESS(ROW(),COLUMN(),4)=$CB$5,1,999) -> 999 | H9: =IF(ADDRESS(ROW(),COLUMN(),4)=$CB$5,1,999) -> 999 | ... S9: =IF(ADDRESS(ROW(),COLUMN(),4)=$CB$5,1,999) -> 999 | T9: =IF(MIN(S9,T8,U9,T10)>MIN(S8,S10,U8,U10),MIN(S8,S10,U8,U10)+SQRT(2),MIN(S9,T8,U9,T10)+1) -> 51.627417 | U9: =IF(MIN(T9,U8,V9,U10)>MIN(T8,T10,V8,V10),MIN(T8,T10,V8,V10)+SQRT(2),MIN(T9,U8,V9,U10)+1) -> 50.627417 | V9: =IF(MIN(U9,V8,W9,V10)>MIN(U8,U10,W8,W10),MIN(U8,U10,W8,W10)+SQRT(2),MIN(U9,V8,W9,V10)+1) -> 49.627417 | W9: =IF(MIN(V9,W8,X9,W10)>MIN(V8,V10,X8,X10),MIN(V8,V10,X8,X10)+SQRT(2),MIN(V9,W8,X9,W10)+1) -> 48.627417 | X9: =IF(MIN(W9,X8,Y9,X10)>MIN(W8,W10,Y8,Y10),MIN(W8,W10,Y8,Y10)+SQRT(2),MIN(W9,X8,Y9,X10)+1) -> 48.213203 | Y9: =IF(ADDRESS(ROW(),COLUMN(),4)=$CB$5,1,999) -> 999 | Z9: =IF(ADDRESS(ROW(),COLUMN(),4)=$CB$5,1,999) -> 999 | AA9: =IF(ADDRESS(ROW(),COLUMN(),4)=$CB$5,1,999) -> 999 | AB9: =IF(ADDRESS(ROW(),COLUMN(),4)=$CB$5,1,999) -> 999 | AC9: =IF(ADDRESS(ROW(),COLUMN(),4)=$CB$5,1,999) -> 999 | AD9: =IF(ADDRESS(ROW(),COLUMN(),4)=$CB$5,1,999) -> 999 | AE9: =IF(ADDRESS(ROW(),COLUMN(),4)=$CB$5,1,999) -> 999 | AF9: =IF(ADDRESS(ROW(),COLUMN(),4)=$CB$5,1,999) -> 999 | ... BX9: =IF(ADDRESS(ROW(),COLUMN(),4)=$CB$5,1,999) -> 999
A10: =IF(ADDRESS(ROW(),COLUMN(),4)=$CB$5,1,999) -> 999 | B10: =IF(ADDRESS(ROW(),COLUMN(),4)=$CB$5,1,999) -> 999 | C10: =IF(ADDRESS(ROW(),COLUMN(),4)=$CB$5,1,999) -> 999 | D10: =IF(ADDRESS(ROW(),COLUMN(),4)=$CB$5,1,999) -> 999 | E10: =IF(ADDRESS(ROW(),COLUMN(),4)=$CB$5,1,999) -> 999 | F10: =IF(ADDRESS(ROW(),COLUMN(),4)=$CB$5,1,999) -> 999 | G10: =IF(ADDRESS(ROW(),COLUMN(),4)=$CB$5,1,999) -> 999 | H10: =IF(ADDRESS(ROW(),COLUMN(),4)=$CB$5,1,999) -> 999 | ... T10: =IF(ADDRESS(ROW(),COLUMN(),4)=$CB$5,1,999) -> 999 | U10: =IF(MIN(T10,U9,V10,U11)>MIN(T9,T11,V9,V11),MIN(T9,T11,V9,V11)+SQRT(2),MIN(T10,U9,V10,U11)+1) -> 50.213203 | V10: =IF(MIN(U10,V9,W10,V11)>MIN(U9,U11,W9,W11),MIN(U9,U11,W9,W11)+SQRT(2),MIN(U10,V9,W10,V11)+1) -> 49.213203 | W10: =IF(MIN(V10,W9,X10,W11)>MIN(V9,V11,X9,X11),MIN(V9,V11,X9,X11)+SQRT(2),MIN(V10,W9,X10,W11)+1) -> 48.213203 | X10: =IF(MIN(W10,X9,Y10,X11)>MIN(W9,W11,Y9,Y11),MIN(W9,W11,Y9,Y11)+SQRT(2),MIN(W10,X9,Y10,X11)+1) -> 47.213203 | Y10: =IF(MIN(X10,Y9,Z10,Y11)>MIN(X9,X11,Z9,Z11),MIN(X9,X11,Z9,Z11)+SQRT(2),MIN(X10,Y9,Z10,Y11)+1) -> 46.79899 | Z10: =IF(ADDRESS(ROW(),COLUMN(),4)=$CB$5,1,999) -> 999 | AA10: =IF(ADDRESS(ROW(),COLUMN(),4)=$CB$5,1,999) -> 999 | AB10: =IF(ADDRESS(ROW(),COLUMN(),4)=$CB$5,1,999) -> 999 | AC10: =IF(ADDRESS(ROW(),COLUMN(),4)=$CB$5,1,999) -> 999 | AD10: =IF(ADDRESS(ROW(),COLUMN(),4)=$CB$5,1,999) -> 999 | AE10: =IF(ADDRESS(ROW(),COLUMN(),4)=$CB$5,1,999) -> 999 | AF10: =IF(ADDRESS(ROW(),COLUMN(),4)=$CB$5,1,999) -> 999 | AG10: =IF(ADDRESS(ROW(),COLUMN(),4)=$CB$5,1,999) -> 999 | ... BX10: =IF(ADDRESS(ROW(),COLUMN(),4)=$CB$5,1,999) -> 999
A11: =IF(ADDRESS(ROW(),COLUMN(),4)=$CB$5,1,999) -> 999 | B11: =IF(ADDRESS(ROW(),COLUMN(),4)=$CB$5,1,999) -> 999 | C11: =IF(ADDRESS(ROW(),COLUMN(),4)=$CB$5,1,999) -> 999 | D11: =IF(ADDRESS(ROW(),COLUMN(),4)=$CB$5,1,999) -> 999 | E11: =IF(ADDRESS(ROW(),COLUMN(),4)=$CB$5,1,999) -> 999 | F11: =IF(ADDRESS(ROW(),COLUMN(),4)=$CB$5,1,999) -> 999 | G11: =IF(ADDRESS(ROW(),COLUMN(),4)=$CB$5,1,999) -> 999 | H11: =IF(ADDRESS(ROW(),COLUMN(),4)=$CB$5,1,999) -> 999 | ... V11: =IF(ADDRESS(ROW(),COLUMN(),4)=$CB$5,1,999) -> 999 | W11: =IF(MIN(V11,W10,X11,W12)>MIN(V10,V12,X10,X12),MIN(V10,V12,X10,X12)+SQRT(2),MIN(V11,W10,X11,W12)+1) -> 47.79899 | X11: =IF(MIN(W11,X10,Y11,X12)>MIN(W10,W12,Y10,Y12),MIN(W10,W12,Y10,Y12)+SQRT(2),MIN(W11,X10,Y11,X12)+1) -> 46.79899 | Y11: =IF(MIN(X11,Y10,Z11,Y12)>MIN(X10,X12,Z10,Z12),MIN(X10,X12,Z10,Z12)+SQRT(2),MIN(X11,Y10,Z11,Y12)+1) -> 45.79899 | Z11: =IF(MIN(Y11,Z10,AA11,Z12)>MIN(Y10,Y12,AA10,AA12),MIN(Y10,Y12,AA10,AA12)+SQRT(2),MIN(Y11,Z10,AA11,Z12)+1) -> 45.384776 | AA11: =IF(ADDRESS(ROW(),COLUMN(),4)=$CB$5,1,999) -> 999 | AB11: =IF(ADDRESS(ROW(),COLUMN(),4)=$CB$5,1,999) -> 999 | AC11: =IF(ADDRESS(ROW(),COLUMN(),4)=$CB$5,1,999) -> 999 | AD11: =IF(ADDRESS(ROW(),COLUMN(),4)=$CB$5,1,999) -> 999 | AE11: =IF(ADDRESS(ROW(),COLUMN(),4)=$CB$5,1,999) -> 999 | AF11: =IF(ADDRESS(ROW(),COLUMN(),4)=$CB$5,1,999) -> 999 | AG11: =IF(ADDRESS(ROW(),COLUMN(),4)=$CB$5,1,999) -> 999 | AH11: =IF(ADDRESS(ROW(),COLUMN(),4)=$CB$5,1,999) -> 999 | ... BX11: =IF(ADDRESS(ROW(),COLUMN(),4)=$CB$5,1,999) -> 999
A12: =IF(ADDRESS(ROW(),COLUMN(),4)=$CB$5,1,999) -> 999 | B12: =IF(ADDRESS(ROW(),COLUMN(),4)=$CB$5,1,999) -> 999 | C12: =IF(ADDRESS(ROW(),COLUMN(),4)=$CB$5,1,999) -> 999 | D12: =IF(ADDRESS(ROW(),COLUMN(),4)=$CB$5,1,999) -> 999 | E12: =IF(ADDRESS(ROW(),COLUMN(),4)=$CB$5,1,999) -> 999 | F12: =IF(ADDRESS(ROW(),COLUMN(),4)=$CB$5,1,999) -> 999 | G12: =IF(ADDRESS(ROW(),COLUMN(),4)=$CB$5,1,999) -> 999 | H12: =IF(ADDRESS(ROW(),COLUMN(),4)=$CB$5,1,999) -> 999 | ... X12: =IF(ADDRESS(ROW(),COLUMN(),4)=$CB$5,1,999) -> 999 | Y12: =IF(MIN(X12,Y11,Z12,Y13)>MIN(X11,X13,Z11,Z13),MIN(X11,X13,Z11,Z13)+SQRT(2),MIN(X12,Y11,Z12,Y13)+1) -> 45.384776 | Z12: =IF(MIN(Y12,Z11,AA12,Z13)>MIN(Y11,Y13,AA11,AA13),MIN(Y11,Y13,AA11,AA13)+SQRT(2),MIN(Y12,Z11,AA12,Z13)+1) -> 44.384776 | AA12: =IF(MIN(Z12,AA11,AB12,AA13)>MIN(Z11,Z13,AB11,AB13),MIN(Z11,Z13,AB11,AB13)+SQRT(2),MIN(Z12,AA11,AB12,AA13)+1) -> 43.970563 | AB12: =IF(MIN(AA12,AB11,AC12,AB13)>MIN(AA11,AA13,AC11,AC13),MIN(AA11,AA13,AC11,AC13)+SQRT(2),MIN(AA12,AB11,AC12,AB13)+1) -> 43.556349 | AC12: =IF(ADDRESS(ROW(),COLUMN(),4)=$CB$5,1,999) -> 999 | AD12: =IF(ADDRESS(ROW(),COLUMN(),4)=$CB$5,1,999) -> 999 | AE12: =IF(ADDRESS(ROW(),COLUMN(),4)=$CB$5,1,999) -> 999 | AF12: =IF(ADDRESS(ROW(),COLUMN(),4)=$CB$5,1,999) -> 999 | AG12: =IF(ADDRESS(ROW(),COLUMN(),4)=$CB$5,1,999) -> 999 | AH12: =IF(ADDRESS(ROW(),COLUMN(),4)=$CB$5,1,999) -> 999 | AI12: =IF(ADDRESS(ROW(),COLUMN(),4)=$CB$5,1,999) -> 999 | AJ12: =IF(ADDRESS(ROW(),COLUMN(),4)=$CB$5,1,999) -> 999 | ... BX12: =IF(ADDRESS(ROW(),COLUMN(),4)=$CB$5,1,999) -> 999
A13: =IF(ADDRESS(ROW(),COLUMN(),4)=$CB$5,1,999) -> 999 | B13: =IF(ADDRESS(ROW(),COLUMN(),4)=$CB$5,1,999) -> 999 | C13: =IF(ADDRESS(ROW(),COLUMN(),4)=$CB$5,1,999) -> 999 | D13: =IF(ADDRESS(ROW(),COLUMN(),4)=$CB$5,1,999) -> 999 | E13: =IF(ADDRESS(ROW(),COLUMN(),4)=$CB$5,1,999) -> 999 | F13: =IF(ADDRESS(ROW(),COLUMN(),4)=$CB$5,1,999) -> 999 | G13: =IF(ADDRESS(ROW(),COLUMN(),4)=$CB$5,1,999) -> 999 | H13: =IF(ADDRESS(ROW(),COLUMN(),4)=$CB$5,1,999) -> 999 | ... Y13: =IF(ADDRESS(ROW(),COLUMN(),4)=$CB$5,1,999) -> 999 | Z13: =IF(MIN(Y13,Z12,AA13,Z14)>MIN(Y12,Y14,AA12,AA14),MIN(Y12,Y14,AA12,AA14)+SQRT(2),MIN(Y13,Z12,AA13,Z14)+1) -> 43.970563 | AA13: =IF(MIN(Z13,AA12,AB13,AA14)>MIN(Z12,Z14,AB12,AB14),MIN(Z12,Z14,AB12,AB14)+SQRT(2),MIN(Z13,AA12,AB13,AA14)+1) -> 42.970563 | AB13: =IF(MIN(AA13,AB12,AC13,AB14)>MIN(AA12,AA14,AC12,AC14),MIN(AA12,AA14,AC12,AC14)+SQRT(2),MIN(AA13,AB12,AC13,AB14)+1) -> 42.556349 | AC13: =IF(MIN(AB13,AC12,AD13,AC14)>MIN(AB12,AB14,AD12,AD14),MIN(AB12,AB14,AD12,AD14)+SQRT(2),MIN(AB13,AC12,AD13,AC14)+1) -> 42.142136 | AD13: =IF(MIN(AC13,AD12,AE13,AD14)>MIN(AC12,AC14,AE12,AE14),MIN(AC12,AC14,AE12,AE14)+SQRT(2),MIN(AC13,AD12,AE13,AD14)+1) -> 41.727922 | AE13: =IF(ADDRESS(ROW(),COLUMN(),4)=$CB$5,1,999) -> 999 | AF13: =IF(ADDRESS(ROW(),COLUMN(),4)=$CB$5,1,999) -> 999 | AG13: =IF(ADDRESS(ROW(),COLUMN(),4)=$CB$5,1,999) -> 999 | AH13: =IF(ADDRESS(ROW(),COLUMN(),4)=$CB$5,1,999) -> 999 | AI13: =IF(ADDRESS(ROW(),COLUMN(),4)=$CB$5,1,999) -> 999 | AJ13: =IF(ADDRESS(ROW(),COLUMN(),4)=$CB$5,1,999) -> 999 | AK13: =IF(ADDRESS(ROW(),COLUMN(),4)=$CB$5,1,999) -> 999 | AL13: =IF(ADDRESS(ROW(),COLUMN(),4)=$CB$5,1,999) -> 999 | ... BX13: =IF(ADDRESS(ROW(),COLUMN(),4)=$CB$5,1,999) -> 999
A14: =IF(ADDRESS(ROW(),COLUMN(),4)=$CB$5,1,999) -> 999 | B14: =IF(ADDRESS(ROW(),COLUMN(),4)=$CB$5,1,999) -> 999 | C14: =IF(ADDRESS(ROW(),COLUMN(),4)=$CB$5,1,999) -> 999 | D14: =IF(ADDRESS(ROW(),COLUMN(),4)=$CB$5,1,999) -> 999 | E14: =IF(ADDRESS(ROW(),COLUMN(),4)=$CB$5,1,999) -> 999 | F14: =IF(ADDRESS(ROW(),COLUMN(),4)=$CB$5,1,999) -> 999 | G14: =IF(ADDRESS(ROW(),COLUMN(),4)=$CB$5,1,999) -> 999 | H14: =IF(ADDRESS(ROW(),COLUMN(),4)=$CB$5,1,999) -> 999 | ... N14: =IF(ADDRESS(ROW(),COLUMN(),4)=$CB$5,1,999) -> 999 | O14: =IF(MIN(N14,O13,P14,O15)>MIN(N13,N15,P13,P15),MIN(N13,N15,P13,P15)+SQRT(2),MIN(N14,O13,P14,O15)+1) -> 20.899495 | P14: =IF(ADDRESS(ROW(),COLUMN(),4)=$CB$5,1,999) -> 999 | Q14: =IF(ADDRESS(ROW(),COLUMN(),4)=$CB$5,1,999) -> 999 | R14: =IF(ADDRESS(ROW(),COLUMN(),4)=$CB$5,1,999) -> 999 | S14: =IF(ADDRESS(ROW(),COLUMN(),4)=$CB$5,1,999) -> 999 | T14: =IF(ADDRESS(ROW(),COLUMN(),4)=$CB$5,1,999) -> 999 | U14: =IF(ADDRESS(ROW(),COLUMN(),4)=$CB$5,1,999) -> 999 | V14: =IF(ADDRESS(ROW(),COLUMN(),4)=$CB$5,1,999) -> 999 | W14: =IF(ADDRESS(ROW(),COLUMN(),4)=$CB$5,1,999) -> 999 | ... AA14: =IF(ADDRESS(ROW(),COLUMN(),4)=$CB$5,1,999) -> 999 | AB14: =IF(MIN(AA14,AB13,AC14,AB15)>MIN(AA13,AA15,AC13,AC15),MIN(AA13,AA15,AC13,AC15)+SQRT(2),MIN(AA14,AB13,AC14,AB15)+1) -> 41.556349 | AC14: =IF(MIN(AB14,AC13,AD14,AC15)>MIN(AB13,AB15,AD13,AD15),MIN(AB13,AB15,AD13,AD15)+SQRT(2),MIN(AB14,AC13,AD14,AC15)+1) -> 41.142136 | AD14: =IF(MIN(AC14,AD13,AE14,AD15)>MIN(AC13,AC15,AE13,AE15),MIN(AC13,AC15,AE13,AE15)+SQRT(2),MIN(AC14,AD13,AE14,AD15)+1) -> 40.727922 | AE14: =IF(MIN(AD14,AE13,AF14,AE15)>MIN(AD13,AD15,AF13,AF15),MIN(AD13,AD15,AF13,AF15)+SQRT(2),MIN(AD14,AE13,AF14,AE15)+1) -> 40.313708 | AF14: =IF(MIN(AE14,AF13,AG14,AF15)>MIN(AE13,AE15,AG13,AG15),MIN(AE13,AE15,AG13,AG15)+SQRT(2),MIN(AE14,AF13,AG14,AF15)+1) -> 39.899495 | AG14: =IF(ADDRESS(ROW(),COLUMN(),4)=$CB$5,1,999) -> 999 | AH14: =IF(ADDRESS(ROW(),COLUMN(),4)=$CB$5,1,999) -> 999 | AI14: =IF(ADDRESS(ROW(),COLUMN(),4)=$CB$5,1,999) -> 999 | AJ14: =IF(ADDRESS(ROW(),COLUMN(),4)=$CB$5,1,999) -> 999 | AK14: =IF(ADDRESS(ROW(),COLUMN(),4)=$CB$5,1,999) -> 999 | AL14: =IF(ADDRESS(ROW(),COLUMN(),4)=$CB$5,1,999) -> 999 | AM14: =IF(ADDRESS(ROW(),COLUMN(),4)=$CB$5,1,999) -> 999 | AN14: =IF(ADDRESS(ROW(),COLUMN(),4)=$CB$5,1,999) -> 999 | ... BX14: =IF(ADDRESS(ROW(),COLUMN(),4)=$CB$5,1,999) -> 999
A15: =IF(ADDRESS(ROW(),COLUMN(),4)=$CB$5,1,999) -> 999 | B15: =IF(ADDRESS(ROW(),COLUMN(),4)=$CB$5,1,999) -> 999 | C15: =IF(ADDRESS(ROW(),COLUMN(),4)=$CB$5,1,999) -> 999 | D15: =IF(ADDRESS(ROW(),COLUMN(),4)=$CB$5,1,999) -> 999 | E15: =IF(ADDRESS(ROW(),COLUMN(),4)=$CB$5,1,999) -> 999 | F15: =IF(ADDRESS(ROW(),COLUMN(),4)=$CB$5,1,999) -> 999 | G15: =IF(ADDRESS(ROW(),COLUMN(),4)=$CB$5,1,999) -> 999 | H15: =IF(ADDRESS(ROW(),COLUMN(),4)=$CB$5,1,999) -> 999 | ... J15: =IF(ADDRESS(ROW(),COLUMN(),4)=$CB$5,1,999) -> 999 | K15: =IF(MIN(J15,K14,L15,K16)>MIN(J14,J16,L14,L16),MIN(J14,J16,L14,L16)+SQRT(2),MIN(J15,K14,L15,K16)+1) -> 22.142136 | L15: =IF(MIN(K15,L14,M15,L16)>MIN(K14,K16,M14,M16),MIN(K14,K16,M14,M16)+SQRT(2),MIN(K15,L14,M15,L16)+1) -> 21.142136 | M15: =IF(MIN(L15,M14,N15,M16)>MIN(L14,L16,N14,N16),MIN(L14,L16,N14,N16)+SQRT(2),MIN(L15,M14,N15,M16)+1) -> 20.727922 | N15: =IF(MIN(M15,N14,O15,N16)>MIN(M14,M16,O14,O16),MIN(M14,M16,O14,O16)+SQRT(2),MIN(M15,N14,O15,N16)+1) -> 20.313708 | O15: =IF(ADDRESS(ROW(),COLUMN(),4)=$CB$5,1,999) -> 999 | P15: =IF(MIN(O15,P14,Q15,P16)>MIN(O14,O16,Q14,Q16),MIN(O14,O16,Q14,Q16)+SQRT(2),MIN(O15,P14,Q15,P16)+1) -> 19.485281 | Q15: =IF(MIN(P15,Q14,R15,Q16)>MIN(P14,P16,R14,R16),MIN(P14,P16,R14,R16)+SQRT(2),MIN(P15,Q14,R15,Q16)+1) -> 19.899495 | R15: =IF(ADDRESS(ROW(),COLUMN(),4)=$CB$5,1,999) -> 999 | S15: =IF(ADDRESS(ROW(),COLUMN(),4)=$CB$5,1,999) -> 999 | T15: =IF(ADDRESS(ROW(),COLUMN(),4)=$CB$5,1,999) -> 999 | U15: =IF(ADDRESS(ROW(),COLUMN(),4)=$CB$5,1,999) -> 999 | V15: =IF(ADDRESS(ROW(),COLUMN(),4)=$CB$5,1,999) -> 999 | W15: =IF(ADDRESS(ROW(),COLUMN(),4)=$CB$5,1,999) -> 999 | X15: =IF(ADDRESS(ROW(),COLUMN(),4)=$CB$5,1,999) -> 999 | Y15: =IF(ADDRESS(ROW(),COLUMN(),4)=$CB$5,1,999) -> 999 | ... AB15: =IF(ADDRESS(ROW(),COLUMN(),4)=$CB$5,1,999) -> 999 | AC15: =IF(MIN(AB15,AC14,AD15,AC16)>MIN(AB14,AB16,AD14,AD16),MIN(AB14,AB16,AD14,AD16)+SQRT(2),MIN(AB15,AC14,AD15,AC16)+1) -> 40.142136 | AD15: =IF(MIN(AC15,AD14,AE15,AD16)>MIN(AC14,AC16,AE14,AE16),MIN(AC14,AC16,AE14,AE16)+SQRT(2),MIN(AC15,AD14,AE15,AD16)+1) -> 39.727922 | AE15: =IF(MIN(AD15,AE14,AF15,AE16)>MIN(AD14,AD16,AF14,AF16),MIN(AD14,AD16,AF14,AF16)+SQRT(2),MIN(AD15,AE14,AF15,AE16)+1) -> 39.313708 | AF15: =IF(MIN(AE15,AF14,AG15,AF16)>MIN(AE14,AE16,AG14,AG16),MIN(AE14,AE16,AG14,AG16)+SQRT(2),MIN(AE15,AF14,AG15,AF16)+1) -> 38.899495 | AG15: =IF(ADDRESS(ROW(),COLUMN(),4)=$CB$5,1,999) -> 999 | AH15: =IF(ADDRESS(ROW(),COLUMN(),4)=$CB$5,1,999) -> 999 | AI15: =IF(ADDRESS(ROW(),COLUMN(),4)=$CB$5,1,999) -> 999 | AJ15: =IF(ADDRESS(ROW(),COLUMN(),4)=$CB$5,1,999) -> 999 | AK15: =IF(ADDRESS(ROW(),COLUMN(),4)=$CB$5,1,999) -> 999 | AL15: =IF(ADDRESS(ROW(),COLUMN(),4)=$CB$5,1,999) -> 999 | AM15: =IF(ADDRESS(ROW(),COLUMN(),4)=$CB$5,1,999) -> 999 | AN15: =IF(ADDRESS(ROW(),COLUMN(),4)=$CB$5,1,999) -> 999 | ... BX15: =IF(ADDRESS(ROW(),COLUMN(),4)=$CB$5,1,999) -> 999
A16: =IF(ADDRESS(ROW(),COLUMN(),4)=$CB$5,1,999) -> 999 | B16: =IF(ADDRESS(ROW(),COLUMN(),4)=$CB$5,1,999) -> 999 | C16: =IF(ADDRESS(ROW(),COLUMN(),4)=$CB$5,1,999) -> 999 | D16: =IF(ADDRESS(ROW(),COLUMN(),4)=$CB$5,1,999) -> 999 | E16: =IF(ADDRESS(ROW(),COLUMN(),4)=$CB$5,1,999) -> 999 | F16: =IF(ADDRESS(ROW(),COLUMN(),4)=$CB$5,1,999) -> 999 | G16: =IF(ADDRESS(ROW(),COLUMN(),4)=$CB$5,1,999) -> 999 | H16: =IF(ADDRESS(ROW(),COLUMN(),4)=$CB$5,1,999) -> 999 | ... K16: =IF(ADDRESS(ROW(),COLUMN(),4)=$CB$5,1,999) -> 999 | L16: =IF(MIN(K16,L15,M16,L17)>MIN(K15,K17,M15,M17),MIN(K15,K17,M15,M17)+SQRT(2),MIN(K16,L15,M16,L17)+1) -> 20.727922 | M16: =IF(MIN(L16,M15,N16,M17)>MIN(L15,L17,N15,N17),MIN(L15,L17,N15,N17)+SQRT(2),MIN(L16,M15,N16,M17)+1) -> 19.727922 | N16: =IF(MIN(M16,N15,O16,N17)>MIN(M15,M17,O15,O17),MIN(M15,M17,O15,O17)+SQRT(2),MIN(M16,N15,O16,N17)+1) -> 19.313708 | O16: =IF(MIN(N16,O15,P16,O17)>MIN(N15,N17,P15,P17),MIN(N15,N17,P15,P17)+SQRT(2),MIN(N16,O15,P16,O17)+1) -> 18.899495 | P16: =IF(MIN(O16,P15,Q16,P17)>MIN(O15,O17,Q15,Q17),MIN(O15,O17,Q15,Q17)+SQRT(2),MIN(O16,P15,Q16,P17)+1) -> 18.485281 | Q16: =IF(MIN(P16,Q15,R16,Q17)>MIN(P15,P17,R15,R17),MIN(P15,P17,R15,R17)+SQRT(2),MIN(P16,Q15,R16,Q17)+1) -> 18.899495 | R16: =IF(MIN(Q16,R15,S16,R17)>MIN(Q15,Q17,S15,S17),MIN(Q15,Q17,S15,S17)+SQRT(2),MIN(Q16,R15,S16,R17)+1) -> 19.313708 | S16: =IF(ADDRESS(ROW(),COLUMN(),4)=$CB$5,1,999) -> 999 | T16: =IF(ADDRESS(ROW(),COLUMN(),4)=$CB$5,1,999) -> 999 | U16: =IF(ADDRESS(ROW(),COLUMN(),4)=$CB$5,1,999) -> 999 | V16: =IF(ADDRESS(ROW(),COLUMN(),4)=$CB$5,1,999) -> 999 | W16: =IF(ADDRESS(ROW(),COLUMN(),4)=$CB$5,1,999) -> 999 | X16: =IF(ADDRESS(ROW(),COLUMN(),4)=$CB$5,1,999) -> 999 | Y16: =IF(ADDRESS(ROW(),COLUMN(),4)=$CB$5,1,999) -> 999 | Z16: =IF(ADDRESS(ROW(),COLUMN(),4)=$CB$5,1,999) -> 999 | ... AB16: =IF(ADDRESS(ROW(),COLUMN(),4)=$CB$5,1,999) -> 999 | AC16: =IF(MIN(AB16,AC15,AD16,AC17)>MIN(AB15,AB17,AD15,AD17),MIN(AB15,AB17,AD15,AD17)+SQRT(2),MIN(AB16,AC15,AD16,AC17)+1) -> 39.142136 | AD16: =IF(MIN(AC16,AD15,AE16,AD17)>MIN(AC15,AC17,AE15,AE17),MIN(AC15,AC17,AE15,AE17)+SQRT(2),MIN(AC16,AD15,AE16,AD17)+1) -> 38.727922 | AE16: =IF(MIN(AD16,AE15,AF16,AE17)>MIN(AD15,AD17,AF15,AF17),MIN(AD15,AD17,AF15,AF17)+SQRT(2),MIN(AD16,AE15,AF16,AE17)+1) -> 38.313708 | AF16: =IF(MIN(AE16,AF15,AG16,AF17)>MIN(AE15,AE17,AG15,AG17),MIN(AE15,AE17,AG15,AG17)+SQRT(2),MIN(AE16,AF15,AG16,AF17)+1) -> 37.899495 | AG16: =IF(ADDRESS(ROW(),COLUMN(),4)=$CB$5,1,999) -> 999 | AH16: =IF(ADDRESS(ROW(),COLUMN(),4)=$CB$5,1,999) -> 999 | AI16: =IF(ADDRESS(ROW(),COLUMN(),4)=$CB$5,1,999) -> 999 | AJ16: =IF(ADDRESS(ROW(),COLUMN(),4)=$CB$5,1,999) -> 999 | AK16: =IF(ADDRESS(ROW(),COLUMN(),4)=$CB$5,1,999) -> 999 | AL16: =IF(ADDRESS(ROW(),COLUMN(),4)=$CB$5,1,999) -> 999 | AM16: =IF(ADDRESS(ROW(),COLUMN(),4)=$CB$5,1,999) -> 999 | AN16: =IF(ADDRESS(ROW(),COLUMN(),4)=$CB$5,1,999) -> 999 | ... BX16: =IF(ADDRESS(ROW(),COLUMN(),4)=$CB$5,1,999) -> 999 | CB16: =MIN(BZ19:CB19,BZ21:CB21,BZ20,CB20)+1 -> 1
A17: =IF(ADDRESS(ROW(),COLUMN(),4)=$CB$5,1,999) -> 999 | B17: =IF(ADDRESS(ROW(),COLUMN(),4)=$CB$5,1,999) -> 999 | C17: =IF(ADDRESS(ROW(),COLUMN(),4)=$CB$5,1,999) -> 999 | D17: =IF(ADDRESS(ROW(),COLUMN(),4)=$CB$5,1,999) -> 999 | E17: =IF(ADDRESS(ROW(),COLUMN(),4)=$CB$5,1,999) -> 999 | F17: =IF(ADDRESS(ROW(),COLUMN(),4)=$CB$5,1,999) -> 999 | G17: =IF(ADDRESS(ROW(),COLUMN(),4)=$CB$5,1,999) -> 999 | H17: =IF(ADDRESS(ROW(),COLUMN(),4)=$CB$5,1,999) -> 999 | ... M17: =IF(ADDRESS(ROW(),COLUMN(),4)=$CB$5,1,999) -> 999 | N17: =IF(MIN(M17,N16,O17,N18)>MIN(M16,M18,O16,O18),MIN(M16,M18,O16,O18)+SQRT(2),MIN(M17,N16,O17,N18)+1) -> 18.313708 | O17: =IF(MIN(N17,O16,P17,O18)>MIN(N16,N18,P16,P18),MIN(N16,N18,P16,P18)+SQRT(2),MIN(N17,O16,P17,O18)+1) -> 17.899495 | P17: =IF(MIN(O17,P16,Q17,P18)>MIN(O16,O18,Q16,Q18),MIN(O16,O18,Q16,Q18)+SQRT(2),MIN(O17,P16,Q17,P18)+1) -> 17.485281 | Q17: =IF(MIN(P17,Q16,R17,Q18)>MIN(P16,P18,R16,R18),MIN(P16,P18,R16,R18)+SQRT(2),MIN(P17,Q16,R17,Q18)+1) -> 17.899495 | R17: =IF(MIN(Q17,R16,S17,R18)>MIN(Q16,Q18,S16,S18),MIN(Q16,Q18,S16,S18)+SQRT(2),MIN(Q17,R16,S17,R18)+1) -> 18.313708 | S17: =IF(MIN(R17,S16,T17,S18)>MIN(R16,R18,T16,T18),MIN(R16,R18,T16,T18)+SQRT(2),MIN(R17,S16,T17,S18)+1) -> 19.313708 | T17: =IF(MIN(S17,T16,U17,T18)>MIN(S16,S18,U16,U18),MIN(S16,S18,U16,U18)+SQRT(2),MIN(S17,T16,U17,T18)+1) -> 20.313708 | U17: =IF(ADDRESS(ROW(),COLUMN(),4)=$CB$5,1,999) -> 999 | V17: =IF(ADDRESS(ROW(),COLUMN(),4)=$CB$5,1,999) -> 999 | W17: =IF(ADDRESS(ROW(),COLUMN(),4)=$CB$5,1,999) -> 999 | X17: =IF(ADDRESS(ROW(),COLUMN(),4)=$CB$5,1,999) -> 999 | Y17: =IF(ADDRESS(ROW(),COLUMN(),4)=$CB$5,1,999) -> 999 | Z17: =IF(ADDRESS(ROW(),COLUMN(),4)=$CB$5,1,999) -> 999 | AA17: =IF(ADDRESS(ROW(),COLUMN(),4)=$CB$5,1,999) -> 999 | AB17: =IF(ADDRESS(ROW(),COLUMN(),4)=$CB$5,1,999) -> 999 | AC17: =IF(MIN(AB17,AC16,AD17,AC18)>MIN(AB16,AB18,AD16,AD18),MIN(AB16,AB18,AD16,AD18)+SQRT(2),MIN(AB17,AC16,AD17,AC18)+1) -> 38.142136 | AD17: =IF(MIN(AC17,AD16,AE17,AD18)>MIN(AC16,AC18,AE16,AE18),MIN(AC16,AC18,AE16,AE18)+SQRT(2),MIN(AC17,AD16,AE17,AD18)+1) -> 37.727922 | AE17: =IF(MIN(AD17,AE16,AF17,AE18)>MIN(AD16,AD18,AF16,AF18),MIN(AD16,AD18,AF16,AF18)+SQRT(2),MIN(AD17,AE16,AF17,AE18)+1) -> 37.313708 | AF17: =IF(MIN(AE17,AF16,AG17,AF18)>MIN(AE16,AE18,AG16,AG18),MIN(AE16,AE18,AG16,AG18)+SQRT(2),MIN(AE17,AF16,AG17,AF18)+1) -> 36.899495 | AG17: =IF(MIN(AF17,AG16,AH17,AG18)>MIN(AF16,AF18,AH16,AH18),MIN(AF16,AF18,AH16,AH18)+SQRT(2),MIN(AF17,AG16,AH17,AG18)+1) -> 37.313708 | AH17: =IF(ADDRESS(ROW(),COLUMN(),4)=$CB$5,1,999) -> 999 | AI17: =IF(ADDRESS(ROW(),COLUMN(),4)=$CB$5,1,999) -> 999 | AJ17: =IF(ADDRESS(ROW(),COLUMN(),4)=$CB$5,1,999) -> 999 | AK17: =IF(ADDRESS(ROW(),COLUMN(),4)=$CB$5,1,999) -> 999 | AL17: =IF(ADDRESS(ROW(),COLUMN(),4)=$CB$5,1,999) -> 999 | AM17: =IF(ADDRESS(ROW(),COLUMN(),4)=$CB$5,1,999) -> 999 | AN17: =IF(ADDRESS(ROW(),COLUMN(),4)=$CB$5,1,999) -> 999 | AO17: =IF(ADDRESS(ROW(),COLUMN(),4)=$CB$5,1,999) -> 999 | ... BX17: =IF(ADDRESS(ROW(),COLUMN(),4)=$CB$5,1,999) -> 999
A18: =IF(ADDRESS(ROW(),COLUMN(),4)=$CB$5,1,999) -> 999 | B18: =IF(ADDRESS(ROW(),COLUMN(),4)=$CB$5,1,999) -> 999 | C18: =IF(ADDRESS(ROW(),COLUMN(),4)=$CB$5,1,999) -> 999 | D18: =IF(ADDRESS(ROW(),COLUMN(),4)=$CB$5,1,999) -> 999 | E18: =IF(ADDRESS(ROW(),COLUMN(),4)=$CB$5,1,999) -> 999 | F18: =IF(ADDRESS(ROW(),COLUMN(),4)=$CB$5,1,999) -> 999 | G18: =IF(ADDRESS(ROW(),COLUMN(),4)=$CB$5,1,999) -> 999 | H18: =IF(ADDRESS(ROW(),COLUMN(),4)=$CB$5,1,999) -> 999 | ... N18: =IF(ADDRESS(ROW(),COLUMN(),4)=$CB$5,1,999) -> 999 | O18: =IF(MIN(N18,O17,P18,O19)>MIN(N17,N19,P17,P19),MIN(N17,N19,P17,P19)+SQRT(2),MIN(N18,O17,P18,O19)+1) -> 16.899495 | P18: =IF(MIN(O18,P17,Q18,P19)>MIN(O17,O19,Q17,Q19),MIN(O17,O19,Q17,Q19)+SQRT(2),MIN(O18,P17,Q18,P19)+1) -> 16.485281 | Q18: =IF(MIN(P18,Q17,R18,Q19)>MIN(P17,P19,R17,R19),MIN(P17,P19,R17,R19)+SQRT(2),MIN(P18,Q17,R18,Q19)+1) -> 16.899495 | R18: =IF(MIN(Q18,R17,S18,R19)>MIN(Q17,Q19,S17,S19),MIN(Q17,Q19,S17,S19)+SQRT(2),MIN(Q18,R17,S18,R19)+1) -> 17.899495 | S18: =IF(ADDRESS(ROW(),COLUMN(),4)=$CB$5,1,999) -> 999 | T18: =IF(MIN(S18,T17,U18,T19)>MIN(S17,S19,U17,U19),MIN(S17,S19,U17,U19)+SQRT(2),MIN(S18,T17,U18,T19)+1) -> 20.727922 | U18: =IF(MIN(T18,U17,V18,U19)>MIN(T17,T19,V17,V19),MIN(T17,T19,V17,V19)+SQRT(2),MIN(T18,U17,V18,U19)+1) -> 21.727922 | V18: =IF(MIN(U18,V17,W18,V19)>MIN(U17,U19,W17,W19),MIN(U17,U19,W17,W19)+SQRT(2),MIN(U18,V17,W18,V19)+1) -> 21.899495 | W18: =IF(MIN(V18,W17,X18,W19)>MIN(V17,V19,X17,X19),MIN(V17,V19,X17,X19)+SQRT(2),MIN(V18,W17,X18,W19)+1) -> 22.899495 | X18: =IF(ADDRESS(ROW(),COLUMN(),4)=$CB$5,1,999) -> 999 | Y18: =IF(ADDRESS(ROW(),COLUMN(),4)=$CB$5,1,999) -> 999 | Z18: =IF(ADDRESS(ROW(),COLUMN(),4)=$CB$5,1,999) -> 999 | AA18: =IF(ADDRESS(ROW(),COLUMN(),4)=$CB$5,1,999) -> 999 | AB18: =IF(ADDRESS(ROW(),COLUMN(),4)=$CB$5,1,999) -> 999 | AC18: =IF(ADDRESS(ROW(),COLUMN(),4)=$CB$5,1,999) -> 999 | AD18: =IF(MIN(AC18,AD17,AE18,AD19)>MIN(AC17,AC19,AE17,AE19),MIN(AC17,AC19,AE17,AE19)+SQRT(2),MIN(AC18,AD17,AE18,AD19)+1) -> 36.727922 | AE18: =IF(MIN(AD18,AE17,AF18,AE19)>MIN(AD17,AD19,AF17,AF19),MIN(AD17,AD19,AF17,AF19)+SQRT(2),MIN(AD18,AE17,AF18,AE19)+1) -> 36.313708 | AF18: =IF(MIN(AE18,AF17,AG18,AF19)>MIN(AE17,AE19,AG17,AG19),MIN(AE17,AE19,AG17,AG19)+SQRT(2),MIN(AE18,AF17,AG18,AF19)+1) -> 35.899495 | AG18: =IF(MIN(AF18,AG17,AH18,AG19)>MIN(AF17,AF19,AH17,AH19),MIN(AF17,AF19,AH17,AH19)+SQRT(2),MIN(AF18,AG17,AH18,AG19)+1) -> 36.313708 | AH18: =IF(MIN(AG18,AH17,AI18,AH19)>MIN(AG17,AG19,AI17,AI19),MIN(AG17,AG19,AI17,AI19)+SQRT(2),MIN(AG18,AH17,AI18,AH19)+1) -> 36.727922 | AI18: =IF(ADDRESS(ROW(),COLUMN(),4)=$CB$5,1,999) -> 999 | AJ18: =IF(ADDRESS(ROW(),COLUMN(),4)=$CB$5,1,999) -> 999 | AK18: =IF(ADDRESS(ROW(),COLUMN(),4)=$CB$5,1,999) -> 999 | AL18: =IF(ADDRESS(ROW(),COLUMN(),4)=$CB$5,1,999) -> 999 | AM18: =IF(ADDRESS(ROW(),COLUMN(),4)=$CB$5,1,999) -> 999 | AN18: =IF(ADDRESS(ROW(),COLUMN(),4)=$CB$5,1,999) -> 999 | AO18: =IF(ADDRESS(ROW(),COLUMN(),4)=$CB$5,1,999) -> 999 | AP18: =IF(ADDRESS(ROW(),COLUMN(),4)=$CB$5,1,999) -> 999 | ... BX18: =IF(ADDRESS(ROW(),COLUMN(),4)=$CB$5,1,999) -> 999
A19: =IF(ADDRESS(ROW(),COLUMN(),4)=$CB$5,1,999) -> 999 | B19: =IF(ADDRESS(ROW(),COLUMN(),4)=$CB$5,1,999) -> 999 | C19: =IF(ADDRESS(ROW(),COLUMN(),4)=$CB$5,1,999) -> 999 | D19: =IF(ADDRESS(ROW(),COLUMN(),4)=$CB$5,1,999) -> 999 | E19: =IF(ADDRESS(ROW(),COLUMN(),4)=$CB$5,1,999) -> 999 | F19: =IF(ADDRESS(ROW(),COLUMN(),4)=$CB$5,1,999) -> 999 | G19: =IF(ADDRESS(ROW(),COLUMN(),4)=$CB$5,1,999) -> 999 | H19: =IF(ADDRESS(ROW(),COLUMN(),4)=$CB$5,1,999) -> 999 | ... O19: =IF(ADDRESS(ROW(),COLUMN(),4)=$CB$5,1,999) -> 999 | P19: =IF(MIN(O19,P18,Q19,P20)>MIN(O18,O20,Q18,Q20),MIN(O18,O20,Q18,Q20)+SQRT(2),MIN(O19,P18,Q19,P20)+1) -> 15.485281 | Q19: =IF(MIN(P19,Q18,R19,Q20)>MIN(P18,P20,R18,R20),MIN(P18,P20,R18,R20)+SQRT(2),MIN(P19,Q18,R19,Q20)+1) -> 16.485281 | R19: =IF(MIN(Q19,R18,S19,R20)>MIN(Q18,Q20,S18,S20),MIN(Q18,Q20,S18,S20)+SQRT(2),MIN(Q19,R18,S19,R20)+1) -> 17.485281 | S19: =IF(ADDRESS(ROW(),COLUMN(),4)=$CB$5,1,999) -> 999 | T19: =IF(ADDRESS(ROW(),COLUMN(),4)=$CB$5,1,999) -> 999 | U19: =IF(MIN(T19,U18,V19,U20)>MIN(T18,T20,V18,V20),MIN(T18,T20,V18,V20)+SQRT(2),MIN(T19,U18,V19,U20)+1) -> 20.485281 | V19: =IF(MIN(U19,V18,W19,V20)>MIN(U18,U20,W18,W20),MIN(U18,U20,W18,W20)+SQRT(2),MIN(U19,V18,W19,V20)+1) -> 21.485281 | W19: =IF(MIN(V19,W18,X19,W20)>MIN(V18,V20,X18,X20),MIN(V18,V20,X18,X20)+SQRT(2),MIN(V19,W18,X19,W20)+1) -> 22.485281 | X19: =IF(ADDRESS(ROW(),COLUMN(),4)=$CB$5,1,999) -> 999 | Y19: =IF(ADDRESS(ROW(),COLUMN(),4)=$CB$5,1,999) -> 999 | Z19: =IF(ADDRESS(ROW(),COLUMN(),4)=$CB$5,1,999) -> 999 | AA19: =IF(ADDRESS(ROW(),COLUMN(),4)=$CB$5,1,999) -> 999 | AB19: =IF(ADDRESS(ROW(),COLUMN(),4)=$CB$5,1,999) -> 999 | AC19: =IF(ADDRESS(ROW(),COLUMN(),4)=$CB$5,1,999) -> 999 | AD19: =IF(ADDRESS(ROW(),COLUMN(),4)=$CB$5,1,999) -> 999 | AE19: =IF(MIN(AD19,AE18,AF19,AE20)>MIN(AD18,AD20,AF18,AF20),MIN(AD18,AD20,AF18,AF20)+SQRT(2),MIN(AD19,AE18,AF19,AE20)+1) -> 35.313708 | AF19: =IF(MIN(AE19,AF18,AG19,AF20)>MIN(AE18,AE20,AG18,AG20),MIN(AE18,AE20,AG18,AG20)+SQRT(2),MIN(AE19,AF18,AG19,AF20)+1) -> 34.899495 | AG19: =IF(MIN(AF19,AG18,AH19,AG20)>MIN(AF18,AF20,AH18,AH20),MIN(AF18,AF20,AH18,AH20)+SQRT(2),MIN(AF19,AG18,AH19,AG20)+1) -> 35.313708 | AH19: =IF(MIN(AG19,AH18,AI19,AH20)>MIN(AG18,AG20,AI18,AI20),MIN(AG18,AG20,AI18,AI20)+SQRT(2),MIN(AG19,AH18,AI19,AH20)+1) -> 35.727922 | AI19: =IF(MIN(AH19,AI18,AJ19,AI20)>MIN(AH18,AH20,AJ18,AJ20),MIN(AH18,AH20,AJ18,AJ20)+SQRT(2),MIN(AH19,AI18,AJ19,AI20)+1) -> 36.142136 | AJ19: =IF(ADDRESS(ROW(),COLUMN(),4)=$CB$5,1,999) -> 999 | AK19: =IF(ADDRESS(ROW(),COLUMN(),4)=$CB$5,1,999) -> 999 | AL19: =IF(ADDRESS(ROW(),COLUMN(),4)=$CB$5,1,999) -> 999 | AM19: =IF(ADDRESS(ROW(),COLUMN(),4)=$CB$5,1,999) -> 999 | AN19: =IF(ADDRESS(ROW(),COLUMN(),4)=$CB$5,1,999) -> 999 | AO19: =IF(ADDRESS(ROW(),COLUMN(),4)=$CB$5,1,999) -> 999 | AP19: =IF(ADDRESS(ROW(),COLUMN(),4)=$CB$5,1,999) -> 999 | AQ19: =IF(ADDRESS(ROW(),COLUMN(),4)=$CB$5,1,999) -> 999 | ... BX19: =IF(ADDRESS(ROW(),COLUMN(),4)=$CB$5,1,999) -> 999
A20: =IF(ADDRESS(ROW(),COLUMN(),4)=$CB$5,1,999) -> 999 | B20: =IF(ADDRESS(ROW(),COLUMN(),4)=$CB$5,1,999) -> 999 | C20: =IF(ADDRESS(ROW(),COLUMN(),4)=$CB$5,1,999) -> 999 | D20: =IF(ADDRESS(ROW(),COLUMN(),4)=$CB$5,1,999) -> 999 | E20: =IF(ADDRESS(ROW(),COLUMN(),4)=$CB$5,1,999) -> 999 | F20: =IF(ADDRESS(ROW(),COLUMN(),4)=$CB$5,1,999) -> 999 | G20: =IF(ADDRESS(ROW(),COLUMN(),4)=$CB$5,1,999) -> 999 | H20: =IF(ADDRESS(ROW(),COLUMN(),4)=$CB$5,1,999) -> 999 | ... N20: =IF(ADDRESS(ROW(),COLUMN(),4)=$CB$5,1,999) -> 999 | O20: =IF(MIN(N20,O19,P20,O21)>MIN(N19,N21,P19,P21),MIN(N19,N21,P19,P21)+SQRT(2),MIN(N20,O19,P20,O21)+1) -> 14.071068 | P20: =IF(MIN(O20,P19,Q20,P21)>MIN(O19,O21,Q19,Q21),MIN(O19,O21,Q19,Q21)+SQRT(2),MIN(O20,P19,Q20,P21)+1) -> 15.071068 | Q20: =IF(MIN(P20,Q19,R20,Q21)>MIN(P19,P21,R19,R21),MIN(P19,P21,R19,R21)+SQRT(2),MIN(P20,Q19,R20,Q21)+1) -> 16.071068 | R20: =IF(MIN(Q20,R19,S20,R21)>MIN(Q19,Q21,S19,S21),MIN(Q19,Q21,S19,S21)+SQRT(2),MIN(Q20,R19,S20,R21)+1) -> 17.071068 | S20: =IF(MIN(R20,S19,T20,S21)>MIN(R19,R21,T19,T21),MIN(R19,R21,T19,T21)+SQRT(2),MIN(R20,S19,T20,S21)+1) -> 18.071068 | T20: =IF(MIN(S20,T19,U20,T21)>MIN(S19,S21,U19,U21),MIN(S19,S21,U19,U21)+SQRT(2),MIN(S20,T19,U20,T21)+1) -> 19.071068 | U20: =IF(ADDRESS(ROW(),COLUMN(),4)=$CB$5,1,999) -> 999 | V20: =IF(MIN(U20,V19,W20,V21)>MIN(U19,U21,W19,W21),MIN(U19,U21,W19,W21)+SQRT(2),MIN(U20,V19,W20,V21)+1) -> 21.071068 | W20: =IF(MIN(V20,W19,X20,W21)>MIN(V19,V21,X19,X21),MIN(V19,V21,X19,X21)+SQRT(2),MIN(V20,W19,X20,W21)+1) -> 22.071068 | X20: =IF(ADDRESS(ROW(),COLUMN(),4)=$CB$5,1,999) -> 999 | Y20: =IF(ADDRESS(ROW(),COLUMN(),4)=$CB$5,1,999) -> 999 | Z20: =IF(ADDRESS(ROW(),COLUMN(),4)=$CB$5,1,999) -> 999 | AA20: =IF(ADDRESS(ROW(),COLUMN(),4)=$CB$5,1,999) -> 999 | AB20: =IF(ADDRESS(ROW(),COLUMN(),4)=$CB$5,1,999) -> 999 | AC20: =IF(ADDRESS(ROW(),COLUMN(),4)=$CB$5,1,999) -> 999 | AD20: =IF(ADDRESS(ROW(),COLUMN(),4)=$CB$5,1,999) -> 999 | AE20: =IF(ADDRESS(ROW(),COLUMN(),4)=$CB$5,1,999) -> 999 | AF20: =IF(MIN(AE20,AF19,AG20,AF21)>MIN(AE19,AE21,AG19,AG21),MIN(AE19,AE21,AG19,AG21)+SQRT(2),MIN(AE20,AF19,AG20,AF21)+1) -> 33.899495 | AG20: =IF(MIN(AF20,AG19,AH20,AG21)>MIN(AF19,AF21,AH19,AH21),MIN(AF19,AF21,AH19,AH21)+SQRT(2),MIN(AF20,AG19,AH20,AG21)+1) -> 34.313708 | AH20: =IF(MIN(AG20,AH19,AI20,AH21)>MIN(AG19,AG21,AI19,AI21),MIN(AG19,AG21,AI19,AI21)+SQRT(2),MIN(AG20,AH19,AI20,AH21)+1) -> 34.727922 | AI20: =IF(MIN(AH20,AI19,AJ20,AI21)>MIN(AH19,AH21,AJ19,AJ21),MIN(AH19,AH21,AJ19,AJ21)+SQRT(2),MIN(AH20,AI19,AJ20,AI21)+1) -> 35.727922 | AJ20: =IF(MIN(AI20,AJ19,AK20,AJ21)>MIN(AI19,AI21,AK19,AK21),MIN(AI19,AI21,AK19,AK21)+SQRT(2),MIN(AI20,AJ19,AK20,AJ21)+1) -> 36.727922 | AK20: =IF(ADDRESS(ROW(),COLUMN(),4)=$CB$5,1,999) -> 999 | AL20: =IF(ADDRESS(ROW(),COLUMN(),4)=$CB$5,1,999) -> 999 | AM20: =IF(ADDRESS(ROW(),COLUMN(),4)=$CB$5,1,999) -> 999 | AN20: =IF(ADDRESS(ROW(),COLUMN(),4)=$CB$5,1,999) -> 999 | AO20: =IF(ADDRESS(ROW(),COLUMN(),4)=$CB$5,1,999) -> 999 | AP20: =IF(ADDRESS(ROW(),COLUMN(),4)=$CB$5,1,999) -> 999 | AQ20: =IF(ADDRESS(ROW(),COLUMN(),4)=$CB$5,1,999) -> 999 | AR20: =IF(ADDRESS(ROW(),COLUMN(),4)=$CB$5,1,999) -> 999 | ... BX20: =IF(ADDRESS(ROW(),COLUMN(),4)=$CB$5,1,999) -> 999
A21: =IF(ADDRESS(ROW(),COLUMN(),4)=$CB$5,1,999) -> 999 | B21: =IF(ADDRESS(ROW(),COLUMN(),4)=$CB$5,1,999) -> 999 | C21: =IF(ADDRESS(ROW(),COLUMN(),4)=$CB$5,1,999) -> 999 | D21: =IF(ADDRESS(ROW(),COLUMN(),4)=$CB$5,1,999) -> 999 | E21: =IF(ADDRESS(ROW(),COLUMN(),4)=$CB$5,1,999) -> 999 | F21: =IF(ADDRESS(ROW(),COLUMN(),4)=$CB$5,1,999) -> 999 | G21: =IF(ADDRESS(ROW(),COLUMN(),4)=$CB$5,1,999) -> 999 | H21: =IF(ADDRESS(ROW(),COLUMN(),4)=$CB$5,1,999) -> 999 | ... M21: =IF(ADDRESS(ROW(),COLUMN(),4)=$CB$5,1,999) -> 999 | N21: =IF(MIN(M21,N20,O21,N22)>MIN(M20,M22,O20,O22),MIN(M20,M22,O20,O22)+SQRT(2),MIN(M21,N20,O21,N22)+1) -> 12.656854 | O21: =IF(MIN(N21,O20,P21,O22)>MIN(N20,N22,P20,P22),MIN(N20,N22,P20,P22)+SQRT(2),MIN(N21,O20,P21,O22)+1) -> 13.656854 | P21: =IF(MIN(O21,P20,Q21,P22)>MIN(O20,O22,Q20,Q22),MIN(O20,O22,Q20,Q22)+SQRT(2),MIN(O21,P20,Q21,P22)+1) -> 14.656854 | Q21: =IF(MIN(P21,Q20,R21,Q22)>MIN(P20,P22,R20,R22),MIN(P20,P22,R20,R22)+SQRT(2),MIN(P21,Q20,R21,Q22)+1) -> 15.656854 | R21: =IF(MIN(Q21,R20,S21,R22)>MIN(Q20,Q22,S20,S22),MIN(Q20,Q22,S20,S22)+SQRT(2),MIN(Q21,R20,S21,R22)+1) -> 16.656854 | S21: =IF(MIN(R21,S20,T21,S22)>MIN(R20,R22,T20,T22),MIN(R20,R22,T20,T22)+SQRT(2),MIN(R21,S20,T21,S22)+1) -> 17.656854 | T21: =IF(MIN(S21,T20,U21,T22)>MIN(S20,S22,U20,U22),MIN(S20,S22,U20,U22)+SQRT(2),MIN(S21,T20,U21,T22)+1) -> 18.656854 | U21: =IF(MIN(T21,U20,V21,U22)>MIN(T20,T22,V20,V22),MIN(T20,T22,V20,V22)+SQRT(2),MIN(T21,U20,V21,U22)+1) -> 19.656854 | ... X21: =IF(MIN(W21,X20,Y21,X22)>MIN(W20,W22,Y20,Y22),MIN(W20,W22,Y20,Y22)+SQRT(2),MIN(W21,X20,Y21,X22)+1) -> 22.656854 | Y21: =IF(ADDRESS(ROW(),COLUMN(),4)=$CB$5,1,999) -> 999 | Z21: =IF(ADDRESS(ROW(),COLUMN(),4)=$CB$5,1,999) -> 999 | AA21: =IF(ADDRESS(ROW(),COLUMN(),4)=$CB$5,1,999) -> 999 | AB21: =IF(ADDRESS(ROW(),COLUMN(),4)=$CB$5,1,999) -> 999 | AC21: =IF(ADDRESS(ROW(),COLUMN(),4)=$CB$5,1,999) -> 999 | AD21: =IF(ADDRESS(ROW(),COLUMN(),4)=$CB$5,1,999) -> 999 | AE21: =IF(ADDRESS(ROW(),COLUMN(),4)=$CB$5,1,999) -> 999 | AF21: =IF(MIN(AE21,AF20,AG21,AF22)>MIN(AE20,AE22,AG20,AG22),MIN(AE20,AE22,AG20,AG22)+SQRT(2),MIN(AE21,AF20,AG21,AF22)+1) -> 32.899495 | AG21: =IF(MIN(AF21,AG20,AH21,AG22)>MIN(AF20,AF22,AH20,AH22),MIN(AF20,AF22,AH20,AH22)+SQRT(2),MIN(AF21,AG20,AH21,AG22)+1) -> 33.313708 | AH21: =IF(MIN(AG21,AH20,AI21,AH22)>MIN(AG20,AG22,AI20,AI22),MIN(AG20,AG22,AI20,AI22)+SQRT(2),MIN(AG21,AH20,AI21,AH22)+1) -> 34.313708 | AI21: =IF(MIN(AH21,AI20,AJ21,AI22)>MIN(AH20,AH22,AJ20,AJ22),MIN(AH20,AH22,AJ20,AJ22)+SQRT(2),MIN(AH21,AI20,AJ21,AI22)+1) -> 35.313708 | AJ21: =IF(MIN(AI21,AJ20,AK21,AJ22)>MIN(AI20,AI22,AK20,AK22),MIN(AI20,AI22,AK20,AK22)+SQRT(2),MIN(AI21,AJ20,AK21,AJ22)+1) -> 36.313708 | AK21: =IF(MIN(AJ21,AK20,AL21,AK22)>MIN(AJ20,AJ22,AL20,AL22),MIN(AJ20,AJ22,AL20,AL22)+SQRT(2),MIN(AJ21,AK20,AL21,AK22)+1) -> 37.313708 | AL21: =IF(MIN(AK21,AL20,AM21,AL22)>MIN(AK20,AK22,AM20,AM22),MIN(AK20,AK22,AM20,AM22)+SQRT(2),MIN(AK21,AL20,AM21,AL22)+1) -> 38.313708 | AM21: =IF(ADDRESS(ROW(),COLUMN(),4)=$CB$5,1,999) -> 999 | AN21: =IF(ADDRESS(ROW(),COLUMN(),4)=$CB$5,1,999) -> 999 | AO21: =IF(ADDRESS(ROW(),COLUMN(),4)=$CB$5,1,999) -> 999 | AP21: =IF(ADDRESS(ROW(),COLUMN(),4)=$CB$5,1,999) -> 999 | AQ21: =IF(ADDRESS(ROW(),COLUMN(),4)=$CB$5,1,999) -> 999 | AR21: =IF(ADDRESS(ROW(),COLUMN(),4)=$CB$5,1,999) -> 999 | AS21: =IF(ADDRESS(ROW(),COLUMN(),4)=$CB$5,1,999) -> 999 | AT21: =IF(ADDRESS(ROW(),COLUMN(),4)=$CB$5,1,999) -> 999 | ... BX21: =IF(ADDRESS(ROW(),COLUMN(),4)=$CB$5,1,999) -> 999
A22: =IF(ADDRESS(ROW(),COLUMN(),4)=$CB$5,1,999) -> 999 | B22: =IF(ADDRESS(ROW(),COLUMN(),4)=$CB$5,1,999) -> 999 | C22: =IF(ADDRESS(ROW(),COLUMN(),4)=$CB$5,1,999) -> 999 | D22: =IF(ADDRESS(ROW(),COLUMN(),4)=$CB$5,1,999) -> 999 | E22: =IF(ADDRESS(ROW(),COLUMN(),4)=$CB$5,1,999) -> 999 | F22: =IF(ADDRESS(ROW(),COLUMN(),4)=$CB$5,1,999) -> 999 | G22: =IF(ADDRESS(ROW(),COLUMN(),4)=$CB$5,1,999) -> 999 | H22: =IF(ADDRESS(ROW(),COLUMN(),4)=$CB$5,1,999) -> 999 | ... K22: =IF(ADDRESS(ROW(),COLUMN(),4)=$CB$5,1,999) -> 999 | L22: =IF(MIN(K22,L21,M22,L23)>MIN(K21,K23,M21,M23),MIN(K21,K23,M21,M23)+SQRT(2),MIN(K22,L21,M22,L23)+1) -> 10.242641 | M22: =IF(MIN(L22,M21,N22,M23)>MIN(L21,L23,N21,N23),MIN(L21,L23,N21,N23)+SQRT(2),MIN(L22,M21,N22,M23)+1) -> 11.242641 | N22: =IF(MIN(M22,N21,O22,N23)>MIN(M21,M23,O21,O23),MIN(M21,M23,O21,O23)+SQRT(2),MIN(M22,N21,O22,N23)+1) -> 12.242641 | O22: =IF(ADDRESS(ROW(),COLUMN(),4)=$CB$5,1,999) -> 999 | P22: =IF(ADDRESS(ROW(),COLUMN(),4)=$CB$5,1,999) -> 999 | Q22: =IF(ADDRESS(ROW(),COLUMN(),4)=$CB$5,1,999) -> 999 | R22: =IF(ADDRESS(ROW(),COLUMN(),4)=$CB$5,1,999) -> 999 | S22: =IF(ADDRESS(ROW(),COLUMN(),4)=$CB$5,1,999) -> 999 | T22: =IF(ADDRESS(ROW(),COLUMN(),4)=$CB$5,1,999) -> 999 | U22: =IF(ADDRESS(ROW(),COLUMN(),4)=$CB$5,1,999) -> 999 | V22: =IF(ADDRESS(ROW(),COLUMN(),4)=$CB$5,1,999) -> 999 | W22: =IF(MIN(V22,W21,X22,W23)>MIN(V21,V23,X21,X23),MIN(V21,V23,X21,X23)+SQRT(2),MIN(V22,W21,X22,W23)+1) -> 22.071068 | X22: =IF(MIN(W22,X21,Y22,X23)>MIN(W21,W23,Y21,Y23),MIN(W21,W23,Y21,Y23)+SQRT(2),MIN(W22,X21,Y22,X23)+1) -> 23.071068 | Y22: =IF(MIN(X22,Y21,Z22,Y23)>MIN(X21,X23,Z21,Z23),MIN(X21,X23,Z21,Z23)+SQRT(2),MIN(X22,Y21,Z22,Y23)+1) -> 24.071068 | Z22: =IF(MIN(Y22,Z21,AA22,Z23)>MIN(Y21,Y23,AA21,AA23),MIN(Y21,Y23,AA21,AA23)+SQRT(2),MIN(Y22,Z21,AA22,Z23)+1) -> 25.071068 | AA22: =IF(MIN(Z22,AA21,AB22,AA23)>MIN(Z21,Z23,AB21,AB23),MIN(Z21,Z23,AB21,AB23)+SQRT(2),MIN(Z22,AA21,AB22,AA23)+1) -> 26.071068 | AB22: =IF(MIN(AA22,AB21,AC22,AB23)>MIN(AA21,AA23,AC21,AC23),MIN(AA21,AA23,AC21,AC23)+SQRT(2),MIN(AA22,AB21,AC22,AB23)+1) -> 27.071068 | AC22: =IF(MIN(AB22,AC21,AD22,AC23)>MIN(AB21,AB23,AD21,AD23),MIN(AB21,AB23,AD21,AD23)+SQRT(2),MIN(AB22,AC21,AD22,AC23)+1) -> 28.071068 | AD22: =IF(ADDRESS(ROW(),COLUMN(),4)=$CB$5,1,999) -> 999 | AE22: =IF(ADDRESS(ROW(),COLUMN(),4)=$CB$5,1,999) -> 999 | AF22: =IF(MIN(AE22,AF21,AG22,AF23)>MIN(AE21,AE23,AG21,AG23),MIN(AE21,AE23,AG21,AG23)+SQRT(2),MIN(AE22,AF21,AG22,AF23)+1) -> 31.899495 | AG22: =IF(MIN(AF22,AG21,AH22,AG23)>MIN(AF21,AF23,AH21,AH23),MIN(AF21,AF23,AH21,AH23)+SQRT(2),MIN(AF22,AG21,AH22,AG23)+1) -> 32.899495 | AH22: =IF(MIN(AG22,AH21,AI22,AH23)>MIN(AG21,AG23,AI21,AI23),MIN(AG21,AG23,AI21,AI23)+SQRT(2),MIN(AG22,AH21,AI22,AH23)+1) -> 33.899495 | AI22: =IF(MIN(AH22,AI21,AJ22,AI23)>MIN(AH21,AH23,AJ21,AJ23),MIN(AH21,AH23,AJ21,AJ23)+SQRT(2),MIN(AH22,AI21,AJ22,AI23)+1) -> 34.899495 | AJ22: =IF(MIN(AI22,AJ21,AK22,AJ23)>MIN(AI21,AI23,AK21,AK23),MIN(AI21,AI23,AK21,AK23)+SQRT(2),MIN(AI22,AJ21,AK22,AJ23)+1) -> 35.899495 | AK22: =IF(MIN(AJ22,AK21,AL22,AK23)>MIN(AJ21,AJ23,AL21,AL23),MIN(AJ21,AJ23,AL21,AL23)+SQRT(2),MIN(AJ22,AK21,AL22,AK23)+1) -> 36.899495 | AL22: =IF(MIN(AK22,AL21,AM22,AL23)>MIN(AK21,AK23,AM21,AM23),MIN(AK21,AK23,AM21,AM23)+SQRT(2),MIN(AK22,AL21,AM22,AL23)+1) -> 37.899495 | AM22: =IF(MIN(AL22,AM21,AN22,AM23)>MIN(AL21,AL23,AN21,AN23),MIN(AL21,AL23,AN21,AN23)+SQRT(2),MIN(AL22,AM21,AN22,AM23)+1) -> 38.899495 | AN22: =IF(MIN(AM22,AN21,AO22,AN23)>MIN(AM21,AM23,AO21,AO23),MIN(AM21,AM23,AO21,AO23)+SQRT(2),MIN(AM22,AN21,AO22,AN23)+1) -> 39.899495 | AO22: =IF(ADDRESS(ROW(),COLUMN(),4)=$CB$5,1,999) -> 999 | AP22: =IF(ADDRESS(ROW(),COLUMN(),4)=$CB$5,1,999) -> 999 | AQ22: =IF(ADDRESS(ROW(),COLUMN(),4)=$CB$5,1,999) -> 999 | AR22: =IF(ADDRESS(ROW(),COLUMN(),4)=$CB$5,1,999) -> 999 | AS22: =IF(MIN(AR22,AS21,AT22,AS23)>MIN(AR21,AR23,AT21,AT23),MIN(AR21,AR23,AT21,AT23)+SQRT(2),MIN(AR22,AS21,AT22,AS23)+1) -> 44.899495 | AT22: =IF(MIN(AS22,AT21,AU22,AT23)>MIN(AS21,AS23,AU21,AU23),MIN(AS21,AS23,AU21,AU23)+SQRT(2),MIN(AS22,AT21,AU22,AT23)+1) -> 45.899495 | AU22: =IF(MIN(AT22,AU21,AV22,AU23)>MIN(AT21,AT23,AV21,AV23),MIN(AT21,AT23,AV21,AV23)+SQRT(2),MIN(AT22,AU21,AV22,AU23)+1) -> 46.899495 | AV22: =IF(ADDRESS(ROW(),COLUMN(),4)=$CB$5,1,999) -> 999 | AW22: =IF(ADDRESS(ROW(),COLUMN(),4)=$CB$5,1,999) -> 999 | AX22: =IF(ADDRESS(ROW(),COLUMN(),4)=$CB$5,1,999) -> 999 | AY22: =IF(ADDRESS(ROW(),COLUMN(),4)=$CB$5,1,999) -> 999 | AZ22: =IF(ADDRESS(ROW(),COLUMN(),4)=$CB$5,1,999) -> 999 | BA22: =IF(ADDRESS(ROW(),COLUMN(),4)=$CB$5,1,999) -> 999 | BB22: =IF(ADDRESS(ROW(),COLUMN(),4)=$CB$5,1,999) -> 999 | BC22: =IF(ADDRESS(ROW(),COLUMN(),4)=$CB$5,1,999) -> 999 | ... BX22: =IF(ADDRESS(ROW(),COLUMN(),4)=$CB$5,1,999) -> 999
A23: =IF(ADDRESS(ROW(),COLUMN(),4)=$CB$5,1,999) -> 999 | B23: =IF(ADDRESS(ROW(),COLUMN(),4)=$CB$5,1,999) -> 999 | C23: =IF(ADDRESS(ROW(),COLUMN(),4)=$CB$5,1,999) -> 999 | D23: =IF(ADDRESS(ROW(),COLUMN(),4)=$CB$5,1,999) -> 1 | E23: =IF(MIN(D23,E22,F23,E24)>MIN(D22,D24,F22,F24),MIN(D22,D24,F22,F24)+SQRT(2),MIN(D23,E22,F23,E24)+1) -> 2 | F23: =IF(MIN(E23,F22,G23,F24)>MIN(E22,E24,G22,G24),MIN(E22,E24,G22,G24)+SQRT(2),MIN(E23,F22,G23,F24)+1) -> 3 | G23: =IF(ADDRESS(ROW(),COLUMN(),4)=$CB$5,1,999) -> 999 | H23: =IF(ADDRESS(ROW(),COLUMN(),4)=$CB$5,1,999) -> 999 | I23: =IF(MIN(H23,I22,J23,I24)>MIN(H22,H24,J22,J24),MIN(H22,H24,J22,J24)+SQRT(2),MIN(H23,I22,J23,I24)+1) -> 6.8284271 | J23: =IF(MIN(I23,J22,K23,J24)>MIN(I22,I24,K22,K24),MIN(I22,I24,K22,K24)+SQRT(2),MIN(I23,J22,K23,J24)+1) -> 7.8284271 | K23: =IF(MIN(J23,K22,L23,K24)>MIN(J22,J24,L22,L24),MIN(J22,J24,L22,L24)+SQRT(2),MIN(J23,K22,L23,K24)+1) -> 8.8284271 | L23: =IF(MIN(K23,L22,M23,L24)>MIN(K22,K24,M22,M24),MIN(K22,K24,M22,M24)+SQRT(2),MIN(K23,L22,M23,L24)+1) -> 9.8284271 | M23: =IF(ADDRESS(ROW(),COLUMN(),4)=$CB$5,1,999) -> 999 | N23: =IF(ADDRESS(ROW(),COLUMN(),4)=$CB$5,1,999) -> 999 | O23: =IF(ADDRESS(ROW(),COLUMN(),4)=$CB$5,1,999) -> 999 | P23: =IF(ADDRESS(ROW(),COLUMN(),4)=$CB$5,1,999) -> 999 | Q23: =IF(ADDRESS(ROW(),COLUMN(),4)=$CB$5,1,999) -> 999 | R23: =IF(ADDRESS(ROW(),COLUMN(),4)=$CB$5,1,999) -> 999 | S23: =IF(ADDRESS(ROW(),COLUMN(),4)=$CB$5,1,999) -> 999 | T23: =IF(ADDRESS(ROW(),COLUMN(),4)=$CB$5,1,999) -> 999 | ... AB23: =IF(ADDRESS(ROW(),COLUMN(),4)=$CB$5,1,999) -> 999 | AC23: =IF(MIN(AB23,AC22,AD23,AC24)>MIN(AB22,AB24,AD22,AD24),MIN(AB22,AB24,AD22,AD24)+SQRT(2),MIN(AB23,AC22,AD23,AC24)+1) -> 28.485281 | AD23: =IF(MIN(AC23,AD22,AE23,AD24)>MIN(AC22,AC24,AE22,AE24),MIN(AC22,AC24,AE22,AE24)+SQRT(2),MIN(AC23,AD22,AE23,AD24)+1) -> 29.485281 | AE23: =IF(MIN(AD23,AE22,AF23,AE24)>MIN(AD22,AD24,AF22,AF24),MIN(AD22,AD24,AF22,AF24)+SQRT(2),MIN(AD23,AE22,AF23,AE24)+1) -> 30.485281 | AF23: =IF(MIN(AE23,AF22,AG23,AF24)>MIN(AE22,AE24,AG22,AG24),MIN(AE22,AE24,AG22,AG24)+SQRT(2),MIN(AE23,AF22,AG23,AF24)+1) -> 31.485281 | AG23: =IF(MIN(AF23,AG22,AH23,AG24)>MIN(AF22,AF24,AH22,AH24),MIN(AF22,AF24,AH22,AH24)+SQRT(2),MIN(AF23,AG22,AH23,AG24)+1) -> 32.485281 | AH23: =IF(MIN(AG23,AH22,AI23,AH24)>MIN(AG22,AG24,AI22,AI24),MIN(AG22,AG24,AI22,AI24)+SQRT(2),MIN(AG23,AH22,AI23,AH24)+1) -> 33.485281 | AI23: =IF(MIN(AH23,AI22,AJ23,AI24)>MIN(AH22,AH24,AJ22,AJ24),MIN(AH22,AH24,AJ22,AJ24)+SQRT(2),MIN(AH23,AI22,AJ23,AI24)+1) -> 34.485281 | AJ23: =IF(MIN(AI23,AJ22,AK23,AJ24)>MIN(AI22,AI24,AK22,AK24),MIN(AI22,AI24,AK22,AK24)+SQRT(2),MIN(AI23,AJ22,AK23,AJ24)+1) -> 35.485281 | ... AV23: =IF(MIN(AU23,AV22,AW23,AV24)>MIN(AU22,AU24,AW22,AW24),MIN(AU22,AU24,AW22,AW24)+SQRT(2),MIN(AU23,AV22,AW23,AV24)+1) -> 47.485281 | AW23: =IF(ADDRESS(ROW(),COLUMN(),4)=$CB$5,1,999) -> 999 | AX23: =IF(ADDRESS(ROW(),COLUMN(),4)=$CB$5,1,999) -> 999 | AY23: =IF(ADDRESS(ROW(),COLUMN(),4)=$CB$5,1,999) -> 999 | AZ23: =IF(ADDRESS(ROW(),COLUMN(),4)=$CB$5,1,999) -> 999 | BA23: =IF(ADDRESS(ROW(),COLUMN(),4)=$CB$5,1,999) -> 999 | BB23: =IF(ADDRESS(ROW(),COLUMN(),4)=$CB$5,1,999) -> 999 | BC23: =IF(ADDRESS(ROW(),COLUMN(),4)=$CB$5,1,999) -> 999 | BD23: =IF(ADDRESS(ROW(),COLUMN(),4)=$CB$5,1,999) -> 999 | ... BX23: =IF(ADDRESS(ROW(),COLUMN(),4)=$CB$5,1,999) -> 999
A24: =IF(ADDRESS(ROW(),COLUMN(),4)=$CB$5,1,999) -> 999 | B24: =IF(ADDRESS(ROW(),COLUMN(),4)=$CB$5,1,999) -> 999 | C24: =IF(ADDRESS(ROW(),COLUMN(),4)=$CB$5,1,999) -> 999 | D24: =IF(ADDRESS(ROW(),COLUMN(),4)=$CB$5,1,999) -> 999 | E24: =IF(ADDRESS(ROW(),COLUMN(),4)=$CB$5,1,999) -> 999 | F24: =IF(MIN(E24,F23,G24,F25)>MIN(E23,E25,G23,G25),MIN(E23,E25,G23,G25)+SQRT(2),MIN(E24,F23,G24,F25)+1) -> 3.4142136 | G24: =IF(MIN(F24,G23,H24,G25)>MIN(F23,F25,H23,H25),MIN(F23,F25,H23,H25)+SQRT(2),MIN(F24,G23,H24,G25)+1) -> 4.4142136 | H24: =IF(MIN(G24,H23,I24,H25)>MIN(G23,G25,I23,I25),MIN(G23,G25,I23,I25)+SQRT(2),MIN(G24,H23,I24,H25)+1) -> 5.4142136 | I24: =IF(MIN(H24,I23,J24,I25)>MIN(H23,H25,J23,J25),MIN(H23,H25,J23,J25)+SQRT(2),MIN(H24,I23,J24,I25)+1) -> 6.4142136 | J24: =IF(MIN(I24,J23,K24,J25)>MIN(I23,I25,K23,K25),MIN(I23,I25,K23,K25)+SQRT(2),MIN(I24,J23,K24,J25)+1) -> 7.4142136 | K24: =IF(ADDRESS(ROW(),COLUMN(),4)=$CB$5,1,999) -> 999 | L24: =IF(ADDRESS(ROW(),COLUMN(),4)=$CB$5,1,999) -> 999 | M24: =IF(ADDRESS(ROW(),COLUMN(),4)=$CB$5,1,999) -> 999 | N24: =IF(ADDRESS(ROW(),COLUMN(),4)=$CB$5,1,999) -> 999 | O24: =IF(ADDRESS(ROW(),COLUMN(),4)=$CB$5,1,999) -> 999 | P24: =IF(ADDRESS(ROW(),COLUMN(),4)=$CB$5,1,999) -> 999 | Q24: =IF(ADDRESS(ROW(),COLUMN(),4)=$CB$5,1,999) -> 999 | R24: =IF(ADDRESS(ROW(),COLUMN(),4)=$CB$5,1,999) -> 999 | ... AD24: =IF(ADDRESS(ROW(),COLUMN(),4)=$CB$5,1,999) -> 999 | AE24: =IF(MIN(AD24,AE23,AF24,AE25)>MIN(AD23,AD25,AF23,AF25),MIN(AD23,AD25,AF23,AF25)+SQRT(2),MIN(AD24,AE23,AF24,AE25)+1) -> 30.899495 | AF24: =IF(MIN(AE24,AF23,AG24,AF25)>MIN(AE23,AE25,AG23,AG25),MIN(AE23,AE25,AG23,AG25)+SQRT(2),MIN(AE24,AF23,AG24,AF25)+1) -> 31.899495 | AG24: =IF(MIN(AF24,AG23,AH24,AG25)>MIN(AF23,AF25,AH23,AH25),MIN(AF23,AF25,AH23,AH25)+SQRT(2),MIN(AF24,AG23,AH24,AG25)+1) -> 32.899495 | AH24: =IF(MIN(AG24,AH23,AI24,AH25)>MIN(AG23,AG25,AI23,AI25),MIN(AG23,AG25,AI23,AI25)+SQRT(2),MIN(AG24,AH23,AI24,AH25)+1) -> 33.899495 | AI24: =IF(MIN(AH24,AI23,AJ24,AI25)>MIN(AH23,AH25,AJ23,AJ25),MIN(AH23,AH25,AJ23,AJ25)+SQRT(2),MIN(AH24,AI23,AJ24,AI25)+1) -> 34.899495 | AJ24: =IF(MIN(AI24,AJ23,AK24,AJ25)>MIN(AI23,AI25,AK23,AK25),MIN(AI23,AI25,AK23,AK25)+SQRT(2),MIN(AI24,AJ23,AK24,AJ25)+1) -> 35.899495 | AK24: =IF(MIN(AJ24,AK23,AL24,AK25)>MIN(AJ23,AJ25,AL23,AL25),MIN(AJ23,AJ25,AL23,AL25)+SQRT(2),MIN(AJ24,AK23,AL24,AK25)+1) -> 36.899495 | AL24: =IF(MIN(AK24,AL23,AM24,AL25)>MIN(AK23,AK25,AM23,AM25),MIN(AK23,AK25,AM23,AM25)+SQRT(2),MIN(AK24,AL23,AM24,AL25)+1) -> 37.899495 | ... BA24: =IF(MIN(AZ24,BA23,BB24,BA25)>MIN(AZ23,AZ25,BB23,BB25),MIN(AZ23,AZ25,BB23,BB25)+SQRT(2),MIN(AZ24,BA23,BB24,BA25)+1) -> 52.899495 | BB24: =IF(ADDRESS(ROW(),COLUMN(),4)=$CB$5,1,999) -> 999 | BC24: =IF(ADDRESS(ROW(),COLUMN(),4)=$CB$5,1,999) -> 999 | BD24: =IF(ADDRESS(ROW(),COLUMN(),4)=$CB$5,1,999) -> 999 | BE24: =IF(ADDRESS(ROW(),COLUMN(),4)=$CB$5,1,999) -> 999 | BF24: =IF(ADDRESS(ROW(),COLUMN(),4)=$CB$5,1,999) -> 999 | BG24: =IF(ADDRESS(ROW(),COLUMN(),4)=$CB$5,1,999) -> 999 | BH24: =IF(ADDRESS(ROW(),COLUMN(),4)=$CB$5,1,999) -> 999 | BI24: =IF(ADDRESS(ROW(),COLUMN(),4)=$CB$5,1,999) -> 999 | ... BX24: =IF(ADDRESS(ROW(),COLUMN(),4)=$CB$5,1,999) -> 999
A25: =IF(ADDRESS(ROW(),COLUMN(),4)=$CB$5,1,999) -> 999 | B25: =IF(ADDRESS(ROW(),COLUMN(),4)=$CB$5,1,999) -> 999 | C25: =IF(ADDRESS(ROW(),COLUMN(),4)=$CB$5,1,999) -> 999 | D25: =IF(ADDRESS(ROW(),COLUMN(),4)=$CB$5,1,999) -> 999 | E25: =IF(ADDRESS(ROW(),COLUMN(),4)=$CB$5,1,999) -> 999 | F25: =IF(ADDRESS(ROW(),COLUMN(),4)=$CB$5,1,999) -> 999 | G25: =IF(ADDRESS(ROW(),COLUMN(),4)=$CB$5,1,999) -> 999 | H25: =IF(ADDRESS(ROW(),COLUMN(),4)=$CB$5,1,999) -> 999 | ... AE25: =IF(ADDRESS(ROW(),COLUMN(),4)=$CB$5,1,999) -> 999 | AF25: =IF(MIN(AE25,AF24,AG25,AF26)>MIN(AE24,AE26,AG24,AG26),MIN(AE24,AE26,AG24,AG26)+SQRT(2),MIN(AE25,AF24,AG25,AF26)+1) -> 32.313708 | AG25: =IF(MIN(AF25,AG24,AH25,AG26)>MIN(AF24,AF26,AH24,AH26),MIN(AF24,AF26,AH24,AH26)+SQRT(2),MIN(AF25,AG24,AH25,AG26)+1) -> 33.313708 | AH25: =IF(MIN(AG25,AH24,AI25,AH26)>MIN(AG24,AG26,AI24,AI26),MIN(AG24,AG26,AI24,AI26)+SQRT(2),MIN(AG25,AH24,AI25,AH26)+1) -> 34.313708 | AI25: =IF(MIN(AH25,AI24,AJ25,AI26)>MIN(AH24,AH26,AJ24,AJ26),MIN(AH24,AH26,AJ24,AJ26)+SQRT(2),MIN(AH25,AI24,AJ25,AI26)+1) -> 35.313708 | AJ25: =IF(MIN(AI25,AJ24,AK25,AJ26)>MIN(AI24,AI26,AK24,AK26),MIN(AI24,AI26,AK24,AK26)+SQRT(2),MIN(AI25,AJ24,AK25,AJ26)+1) -> 36.313708 | AK25: =IF(MIN(AJ25,AK24,AL25,AK26)>MIN(AJ24,AJ26,AL24,AL26),MIN(AJ24,AJ26,AL24,AL26)+SQRT(2),MIN(AJ25,AK24,AL25,AK26)+1) -> 37.313708 | AL25: =IF(MIN(AK25,AL24,AM25,AL26)>MIN(AK24,AK26,AM24,AM26),MIN(AK24,AK26,AM24,AM26)+SQRT(2),MIN(AK25,AL24,AM25,AL26)+1) -> 38.313708 | AM25: =IF(MIN(AL25,AM24,AN25,AM26)>MIN(AL24,AL26,AN24,AN26),MIN(AL24,AL26,AN24,AN26)+SQRT(2),MIN(AL25,AM24,AN25,AM26)+1) -> 39.313708 | ... BA25: =IF(MIN(AZ25,BA24,BB25,BA26)>MIN(AZ24,AZ26,BB24,BB26),MIN(AZ24,AZ26,BB24,BB26)+SQRT(2),MIN(AZ25,BA24,BB25,BA26)+1) -> 53.313708 | BB25: =IF(ADDRESS(ROW(),COLUMN(),4)=$CB$5,1,999) -> 999 | BC25: =IF(ADDRESS(ROW(),COLUMN(),4)=$CB$5,1,999) -> 999 | BD25: =IF(ADDRESS(ROW(),COLUMN(),4)=$CB$5,1,999) -> 999 | BE25: =IF(ADDRESS(ROW(),COLUMN(),4)=$CB$5,1,999) -> 999 | BF25: =IF(ADDRESS(ROW(),COLUMN(),4)=$CB$5,1,999) -> 999 | BG25: =IF(ADDRESS(ROW(),COLUMN(),4)=$CB$5,1,999) -> 999 | BH25: =IF(ADDRESS(ROW(),COLUMN(),4)=$CB$5,1,999) -> 999 | BI25: =IF(ADDRESS(ROW(),COLUMN(),4)=$CB$5,1,999) -> 999 | ... BX25: =IF(ADDRESS(ROW(),COLUMN(),4)=$CB$5,1,999) -> 999 | CB25: 2 | CC25: =SQRT(2) -> 1.4142136
